Workbook

Sheet Summary
A1: Four-bar angular velocities
A4: Comparison | B4: Sensor N | C4: RMSE (360-grid) | D4: PMKS paired N | E4: Unit
A5: Coupler BNO055(1) | B5: =COUNT('Paired Data'!B6:B140) -> 135 | C5: =SQRT(SUM('Paired Data'!E6:E140)/B5) -> 0.067833979 | D5: =COUNT('Paired Data'!D6:D140) -> 135 | E5: rad/s
A6: Coupler MPU6050 | B6: =COUNT('Paired Data'!B6:B140) -> 135 | C6: =SQRT(SUM('Paired Data'!H6:H140)/B6) -> 0.076611009 | D6: =COUNT('Paired Data'!G6:G140) -> 135 | E6: rad/s
A7: Follower BNO055(2) | B7: =COUNT('Paired Data'!B6:B140) -> 135 | C7: =SQRT(SUM('Paired Data'!K6:K140)/B7) -> 0.075544055 | D7: =COUNT('Paired Data'!J6:J140) -> 135 | E7: rad/s
A10: Tachometer speed (rpm) | B10: 20
A11: Nominal period (ms) | B11: =60000/B10 -> 3000
A12: Native sample count | B12: =COUNT('Native PMKS'!A6:A366) -> 361
A13: Native intervals | B13: =B12-1 -> 360
A14: Native time step (ms) | B14: =B11/B13 -> 8.3333333
A15: Instructor grid sample count | B15: 360
A16: Instructor grid intervals | B16: =B15-1 -> 359
A17: Instructor time step (ms) | B17: =B11/B16 -> 8.356546
A18: Hall crank phase estimate (deg) | B18: 359.36899
A19: Native initial crank angle (deg) | B19: =DEGREES(ATAN2('Native PMKS'!D6,'Native PMKS'!E6)) -> 0
A20: Phase shift (ms) | B20: =MOD(B18-B19,360)/360*B11 -> 2994.7416
A21: First source data row | B21: 694
A22: Last source data row | B22: 828
A23: Next Hall event time (ms) | B23: 17809
A24: Selected cycle period (ms) | B24: =B23-'BNO1 Rate'!B6 -> 2934
A25: Selected Hall speed (rpm) | B25: =60000/B24 -> 20.449898

Sheet Paired Data
A1: Extracted sensor and time-matched PMKS data
A5: Source row | B5: Elapsed time (ms) | C5: BNO1 measured (rad/s) | D5: BNO1 PMKS (rad/s) | E5: BNO1 squared error | F5: MPU measured (rad/s) | G5: MPU PMKS (rad/s) | H5: MPU squared error | I5: BNO2 measured (rad/s) | J5: BNO2 PMKS (rad/s) | K5: BNO2 squared error
A6: ='BNO1 Rate'!A6 -> 694 | B6: ='BNO1 Rate'!C6 -> 0 | C6: ='BNO1 Rate'!K6 -> -1.1017391 | D6: ='BNO1 Rate'!T6 -> -1.0411034 | E6: =(C6-D6)^2 -> 0.0036766901 | F6: ='MPU Rate'!K6 -> -1.086084 | G6: ='MPU Rate'!T6 -> -1.0411034 | H6: =(F6-G6)^2 -> 0.0020232535 | I6: ='BNO2 Rate'!K6 -> -1.2871803 | J6: ='BNO2 Rate'!T6 -> -1.0581424 | K6: =(I6-J6)^2 -> 0.052458362
A7: ='BNO1 Rate'!A7 -> 695 | B7: ='BNO1 Rate'!C7 -> 21 | C7: ='BNO1 Rate'!K7 -> -1.1093749 | D7: ='BNO1 Rate'!T7 -> -1.0468893 | E7: =(C7-D7)^2 -> 0.003904449 | F7: ='MPU Rate'!K7 -> -1.1353796 | G7: ='MPU Rate'!T7 -> -1.0468893 | H7: =(F7-G7)^2 -> 0.0078305319 | I7: ='BNO2 Rate'!K7 -> -1.2173672 | J7: ='BNO2 Rate'!T7 -> -0.99576513 | K7: =(I7-J7)^2 -> 0.049107455
A8: ='BNO1 Rate'!A8 -> 696 | B8: ='BNO1 Rate'!C8 -> 41 | C8: ='BNO1 Rate'!K8 -> -1.154099 | D8: ='BNO1 Rate'!T8 -> -1.0477075 | E8: =(C8-D8)^2 -> 0.011319139 | F8: ='MPU Rate'!K8 -> -1.1313826 | G8: ='MPU Rate'!T8 -> -1.0477075 | H8: =(F8-G8)^2 -> 0.0070015184 | I8: ='BNO2 Rate'!K8 -> -1.1868239 | J8: ='BNO2 Rate'!T8 -> -0.92990397 | K8: =(I8-J8)^2 -> 0.066007845
A9: ='BNO1 Rate'!A9 -> 697 | B9: ='BNO1 Rate'!C9 -> 62 | C9: ='BNO1 Rate'!K9 -> -1.1650073 | D9: ='BNO1 Rate'!T9 -> -1.042573 | E9: =(C9-D9)^2 -> 0.014990147 | F9: ='MPU Rate'!K9 -> -1.1598941 | G9: ='MPU Rate'!T9 -> -1.042573 | H9: =(F9-G9)^2 -> 0.013764245 | I9: ='BNO2 Rate'!K9 -> -1.121374 | J9: ='BNO2 Rate'!T9 -> -0.8567301 | K9: =(I9-J9)^2 -> 0.070036419
A10: ='BNO1 Rate'!A10 -> 698 | B10: ='BNO1 Rate'!C10 -> 104 | C10: ='BNO1 Rate'!K10 -> -1.1704614 | D10: ='BNO1 Rate'!T10 -> -1.018057 | E10: =(C10-D10)^2 -> 0.023227117 | F10: ='MPU Rate'!K10 -> -1.1556308 | G10: ='MPU Rate'!T10 -> -1.018057 | H10: =(F10-G10)^2 -> 0.018926561 | I10: ='BNO2 Rate'!K10 -> -0.92284284 | J10: ='BNO2 Rate'!T10 -> -0.69980525 | K10: =(I10-J10)^2 -> 0.049745769
A11: ='BNO1 Rate'!A11 -> 699 | B11: ='BNO1 Rate'!C11 -> 125 | C11: ='BNO1 Rate'!K11 -> -1.1879147 | D11: ='BNO1 Rate'!T11 -> -0.99903458 | E11: =(C11-D11)^2 -> 0.035675709 | F11: ='MPU Rate'!K11 -> -1.1097991 | G11: ='MPU Rate'!T11 -> -0.99903458 | H11: =(F11-G11)^2 -> 0.01226879 | I11: ='BNO2 Rate'!K11 -> -0.86393798 | J11: ='BNO2 Rate'!T11 -> -0.61646747 | K11: =(I11-J11)^2 -> 0.061241651
A12: ='BNO1 Rate'!A12 -> 700 | B12: ='BNO1 Rate'!C12 -> 145 | C12: ='BNO1 Rate'!K12 -> -1.154099 | D12: ='BNO1 Rate'!T12 -> -0.97804486 | E12: =(C12-D12)^2 -> 0.030995049 | F12: ='MPU Rate'!K12 -> -1.1018053 | G12: ='MPU Rate'!T12 -> -0.97804486 | H12: =(F12-G12)^2 -> 0.015316639 | I12: ='BNO2 Rate'!K12 -> -0.74503742 | J12: ='BNO2 Rate'!T12 -> -0.53588859 | K12: =(I12-J12)^2 -> 0.043743233
A13: ='BNO1 Rate'!A13 -> 701 | B13: ='BNO1 Rate'!C13 -> 166 | C13: ='BNO1 Rate'!K13 -> -1.1399182 | D13: ='BNO1 Rate'!T13 -> -0.95282145 | E13: =(C13-D13)^2 -> 0.035005181 | F13: ='MPU Rate'!K13 -> -1.0362556 | G13: ='MPU Rate'!T13 -> -0.95282145 | H13: =(F13-G13)^2 -> 0.0069612494 | I13: ='BNO2 Rate'!K13 -> -0.66213428 | J13: ='BNO2 Rate'!T13 -> -0.45117475 | K13: =(I13-J13)^2 -> 0.044503924
A14: ='BNO1 Rate'!A14 -> 702 | B14: ='BNO1 Rate'!C14 -> 186 | C14: ='BNO1 Rate'!K14 -> -1.083195 | D14: ='BNO1 Rate'!T14 -> -0.92638276 | E14: =(C14-D14)^2 -> 0.024590067 | F14: ='MPU Rate'!K14 -> -1.0242647 | G14: ='MPU Rate'!T14 -> -0.92638276 | H14: =(F14-G14)^2 -> 0.0095808678 | I14: ='BNO2 Rate'!K14 -> -0.53341625 | J14: ='BNO2 Rate'!T14 -> -0.36957407 | K14: =(I14-J14)^2 -> 0.026844262
A15: ='BNO1 Rate'!A15 -> 703 | B15: ='BNO1 Rate'!C15 -> 206 | C15: ='BNO1 Rate'!K15 -> -1.0602875 | D15: ='BNO1 Rate'!T15 -> -0.89793203 | E15: =(C15-D15)^2 -> 0.026359304 | F15: ='MPU Rate'!K15 -> -0.96271196 | G15: ='MPU Rate'!T15 -> -0.89793203 | H15: =(F15-G15)^2 -> 0.0041964389 | I15: ='BNO2 Rate'!K15 -> -0.44833145 | J15: ='BNO2 Rate'!T15 -> -0.28897621 | K15: =(I15-J15)^2 -> 0.025394092
A16: ='BNO1 Rate'!A16 -> 704 | B16: ='BNO1 Rate'!C16 -> 228 | C16: ='BNO1 Rate'!K16 -> -1.0133818 | D16: ='BNO1 Rate'!T16 -> -0.86552343 | E16: =(C16-D16)^2 -> 0.021862096 | F16: ='MPU Rate'!K16 -> -0.94086192 | G16: ='MPU Rate'!T16 -> -0.86552343 | H16: =(F16-G16)^2 -> 0.0056758883 | I16: ='BNO2 Rate'!K16 -> -0.33379422 | J16: ='BNO2 Rate'!T16 -> -0.20099278 | K16: =(I16-J16)^2 -> 0.017636222
A17: ='BNO1 Rate'!A17 -> 705 | B17: ='BNO1 Rate'!C17 -> 249 | C17: ='BNO1 Rate'!K17 -> -0.97956604 | D17: ='BNO1 Rate'!T17 -> -0.83276335 | E17: =(C17-D17)^2 -> 0.021551031 | F17: ='MPU Rate'!K17 -> -0.88570426 | G17: ='MPU Rate'!T17 -> -0.83276335 | H17: =(F17-G17)^2 -> 0.0028027404 | I17: ='BNO2 Rate'!K17 -> -0.2443461 | J17: ='BNO2 Rate'!T17 -> -0.11904666 | K17: =(I17-J17)^2 -> 0.015699949
... A140: ='BNO1 Rate'!A140 -> 828 | B140: ='BNO1 Rate'!C140 -> 2903 | C140: ='BNO1 Rate'!K140 -> -1.0286534 | D140: ='BNO1 Rate'!T140 -> -0.93292572 | E140: =(C140-D140)^2 -> 0.0091637933 | F140: ='MPU Rate'!K140 -> -1.0391866 | G140: ='MPU Rate'!T140 -> -0.93292572 | H140: =(F140-G140)^2 -> 0.01129138 | I140: ='BNO2 Rate'!K140 -> -1.3144511 | J140: ='BNO2 Rate'!T140 -> -1.2627101 | K140: =(I140-J140)^2 -> 0.0026771299

Sheet Raw Data
A1: Raw Data
A5: source_row | B5: Time | C5: Hall | D5: RPM | E5: EncoderAngularVelocity | F5: BNO1GyroX | G5: BNO1GyroY | H5: BNO1GyroZ | I5: BNO1AngleX | J5: BNO1AngleY | K5: BNO1AngleZ | L5: BNO2GyroX | M5: BNO2GyroY | N5: BNO2GyroZ | O5: BNO2AngleX | P5: BNO2AngleY | Q5: BNO2AngleZ | R5: MPUGyroX | S5: MPUGyroY | T5: MPUGyroZ | U5: MPUAngleX | V5: MPUAngleY | W5: MPUAngleZ
A6: 2 | B6: 0 | C6: 1 | D6: 0 | E6: 0 | F6: -0.125 | G6: 0.125 | H6: -0.0625 | I6: 1.6875 | J6: -2.125 | K6: -15.125 | L6: -0.0625 | M6: -0.125 | N6: -0.1875 | O6: 0.8125 | P6: -2.0625 | Q6: -39.125 | R6: 0.079573393 | S6: 0.044825077 | T6: -0.23746583 | U6: 1.2190967 | V6: -33.216381 | W6: -17.514181
A7: 3 | B7: 22 | C7: 1 | D7: 0 | E7: 0 | F7: 0 | G7: 0.0625 | H7: 0 | I7: 1.6875 | J7: -2.125 | K7: -15.125 | L7: 0 | M7: 0.0625 | N7: -0.125 | O7: 0.8125 | P7: -2.0625 | Q7: -39.125 | R7: 0.01850462 | S7: -0.00097644329 | T7: -0.22219867 | U7: 1.2174582 | V7: -33.224339 | W7: -17.517145
A8: 4 | B8: 62 | C8: 1 | D8: 0 | E8: 0 | F8: 0 | G8: 0 | H8: 0 | I8: 1.6875 | J8: -2.125 | K8: -15.125 | L8: -0.125 | M8: -0.0625 | N8: -0.0625 | O8: 0.8125 | P8: -2.0625 | Q8: -39.125 | R8: 0.094840527 | S8: -0.10784674 | T8: -0.17639714 | U8: 1.221464 | V8: -33.224194 | W8: -17.523584
A9: 5 | B9: 84 | C9: 1 | D9: 0 | E9: 0 | F9: 0.0625 | G9: -0.0625 | H9: 0 | I9: 1.6875 | J9: -2.125 | K9: -15.125 | L9: -0.0625 | M9: 0 | N9: -0.0625 | O9: 0.8125 | P9: -2.0625 | Q9: -39.125 | R9: 0.01850462 | S9: -0.00097644329 | T9: -0.13059562 | U9: 1.2293253 | V9: -33.226143 | W9: -17.525074
A10: 6 | B10: 104 | C10: 1 | D10: 0 | E10: 0 | F10: 0.0625 | G10: 0.1875 | H10: 0.125 | I10: 1.6875 | J10: -2.125 | K10: -15.125 | L10: 0 | M10: 0 | N10: 0 | O10: 0.8125 | P10: -2.0625 | Q10: -39.125 | R10: -0.02729702 | S10: -0.07731235 | T10: 0.02207613 | U10: 1.2222404 | V10: -33.240364 | W10: -17.526417
A11: 7 | B11: 127 | C11: 1 | D11: 0 | E11: 0 | F11: 0.125 | G11: 0 | H11: -0.0625 | I11: 1.6875 | J11: -2.125 | K11: -15.125 | L11: 0.0625 | M11: -0.125 | N11: 0.0625 | O11: 0.8125 | P11: -2.0625 | Q11: -39.125 | R11: 0.11010766 | S11: 0.15169525 | T11: -0.25273302 | U11: 1.2481502 | V11: -33.224365 | W11: -17.528152
A12: 8 | B12: 148 | C12: 1 | D12: 0 | E12: 0 | F12: 0 | G12: 0.0625 | H12: -0.1875 | I12: 1.6875 | J12: -2.125 | K12: -15.125 | L12: 0 | M12: 0 | N12: -0.125 | O12: 0.8125 | P12: -2.0625 | Q12: -39.125 | R12: -0.02729702 | S12: 0.21276397 | T12: 0.0068089962 | U12: 1.2192187 | V12: -33.225029 | W12: -17.529955
A13: 9 | B13: 171 | C13: 1 | D13: 0 | E13: 0 | F13: -0.0625 | G13: 0.0625 | H13: -0.0625 | I13: 1.6875 | J13: -2.125 | K13: -15.125 | L13: 0.0625 | M13: -0.0625 | N13: 0 | O13: 0.8125 | P13: -2.0625 | Q13: -39.125 | R13: 0.079573393 | S13: -0.046777964 | T13: -0.10006124 | U13: 1.2294608 | V13: -33.239582 | W13: -17.531883
A14: 10 | B14: 193 | C14: 1 | D14: 0 | E14: 0 | F14: -0.0625 | G14: 0.0625 | H14: 0 | I14: 1.6875 | J14: -2.125 | K14: -15.125 | L14: 0 | M14: -0.125 | N14: 0.0625 | O14: 0.8125 | P14: -2.0625 | Q14: -39.125 | R14: 0.079573393 | S14: -0.00097644329 | T14: 0.083144844 | U14: 1.2214066 | V14: -33.232269 | W14: -17.532885
A15: 11 | B15: 214 | C15: 1 | D15: 0 | E15: 0 | F15: -0.0625 | G15: -0.0625 | H15: 0.1875 | I15: 1.6875 | J15: -2.125 | K15: -15.125 | L15: 0 | M15: -0.0625 | N15: 0.125 | O15: 0.8125 | P15: -2.0625 | Q15: -39.125 | R15: -0.28683901 | S15: -0.13838112 | T15: -0.038992584 | U15: 1.2319323 | V15: -33.244698 | W15: -17.5343
A16: 12 | B16: 234 | C16: 1 | D16: 0 | E16: 0 | F16: 0 | G16: 0.25 | H16: -0.25 | I16: 1.6875 | J16: -2.125 | K16: -15.125 | L16: 0 | M16: 0.0625 | N16: 0.125 | O16: 0.8125 | P16: -2.0625 | Q16: -39.125 | R16: -0.19523597 | S16: -0.092579484 | T16: -0.084794104 | U16: 1.2268274 | V16: -33.238583 | W16: -17.534826
A17: 13 | B17: 257 | C17: 1 | D17: 0 | E17: 0 | F17: 0.0625 | G17: -0.0625 | H17: 0 | I17: 1.6875 | J17: -2.125 | K17: -15.125 | L17: -0.0625 | M17: -0.125 | N17: 0 | O17: 0.8125 | P17: -2.0625 | Q17: -39.125 | R17: 0.11010766 | S17: 0.060092211 | T17: 0.052610517 | U17: 1.2379901 | V17: -33.23592 | W17: -17.535852
... A1371: 1367 | B1371: 29391 | C1371: 1 | D1371: 0 | E1371: 0 | F1371: -31.4375 | G1371: -0.3125 | H1371: 0.3125 | I1371: 1.3125 | J1371: -2.25 | K1371: -15.625 | L1371: -76.25 | M1371: 0.9375 | N1371: 0.125 | O1371: 0.5 | P1371: -2.25 | Q1371: -16.0625 | R1371: -1.5540147 | S1371: 36.258568 | T1371: 0.098412037 | U1371: 1.2960407 | V1371: -33.458496 | W1371: -18.904125

Sheet Native PMKS
A1: Native PMKS exports and calculated coordinates
A5: Step | B5: Exported time (s) | C5: Calculated time (ms) | D5: B x (cm) | E5: B y (cm) | F5: D x (cm) | G5: D y (cm) | H5: E x (cm) | I5: E y (cm) | J5: F x (cm) | K5: F y (cm) | L5: G x (cm) | M5: G y (cm) | N5: Coupler rate (deg/s) | O5: Follower rate (deg/s) | P5: BF angle (deg) | Q5: BG angle (deg) | R5: DE angle (deg) | S5: BF unwrapped (deg) | T5: BG unwrapped (deg) | U5: DE unwrapped (deg) | V5: Time difference (ms)
A6: 0 | B6: 0 | C6: =TimeStep!B6 -> 0 | D6: 1.52 | E6: 0 | F6: 4.572 | G6: 0 | H6: 4.79 | I6: 1.632 | J6: 2.548 | K6: 1.958 | L6: 2.053 | M6: 3.543 | N6: -59.7595 | O6: -59.7595 | P6: =DEGREES(ATAN2(J6-D6,K6-E6)) -> 62.29938 | Q6: =DEGREES(ATAN2(L6-D6,M6-E6)) -> 81.444722 | R6: =DEGREES(ATAN2(H6-F6,I6-G6)) -> 82.391559 | S6: =P6 -> 62.29938 | T6: =Q6 -> 81.444722 | U6: =R6 -> 82.391559 | V6: =C6-B6*1000 -> 0
A7: 1 | B7: 0.0083333333 | C7: =TimeStep!B7 -> 8.3333333 | D7: 1.52 | E7: 0.027 | F7: 4.572 | G7: 0 | H7: 4.804 | I7: 1.63 | J7: 2.565 | K7: 1.976 | L7: 2.084 | M7: 3.565 | N7: -59.9314 | O7: -58.3271 | P7: =DEGREES(ATAN2(J7-D7,K7-E7)) -> 61.801019 | Q7: =DEGREES(ATAN2(L7-D7,M7-E7)) -> 80.94257 | R7: =DEGREES(ATAN2(H7-F7,I7-G7)) -> 81.899426 | S7: =S6+MOD(P7-P6+180,360)-180 -> 61.801019 | T7: =T6+MOD(Q7-Q6+180,360)-180 -> 80.94257 | U7: =U6+MOD(R7-R6+180,360)-180 -> 81.899426 | V7: =C7-B7*1000 -> 3.375078e-14
A8: 2 | B8: 0.016666667 | C8: =TimeStep!B8 -> 16.666667 | D8: 1.519 | E8: 0.053 | F8: 4.572 | G8: 0 | H8: 4.818 | I8: 1.628 | J8: 2.581 | K8: 1.993 | L8: 2.114 | M8: 3.586 | N8: -59.9887 | O8: -56.8947 | P8: =DEGREES(ATAN2(J8-D8,K8-E8)) -> 61.302704 | Q8: =DEGREES(ATAN2(L8-D8,M8-E8)) -> 80.440402 | R8: =DEGREES(ATAN2(H8-F8,I8-G8)) -> 81.407289 | S8: =S7+MOD(P8-P7+180,360)-180 -> 61.302704 | T8: =T7+MOD(Q8-Q7+180,360)-180 -> 80.440402 | U8: =U7+MOD(R8-R7+180,360)-180 -> 81.407289 | V8: =C8-B8*1000 -> 6.750156e-14
A9: 3 | B9: 0.025 | C9: =TimeStep!B9 -> 25 | D9: 1.518 | E9: 0.08 | F9: 4.572 | G9: 0 | H9: 4.831 | I9: 1.626 | J9: 2.597 | K9: 2.01 | L9: 2.143 | M9: 3.607 | N9: -60.046 | O9: -55.3477 | P9: =DEGREES(ATAN2(J9-D9,K9-E9)) -> 60.791869 | Q9: =DEGREES(ATAN2(L9-D9,M9-E9)) -> 79.95125 | R9: =DEGREES(ATAN2(H9-F9,I9-G9)) -> 80.949582 | S9: =S8+MOD(P9-P8+180,360)-180 -> 60.791869 | T9: =T8+MOD(Q9-Q8+180,360)-180 -> 79.95125 | U9: =U8+MOD(R9-R8+180,360)-180 -> 80.949582 | V9: =C9-B9*1000 -> 0
A10: 4 | B10: 0.033333333 | C10: =TimeStep!B10 -> 33.333333 | D10: 1.516 | E10: 0.106 | F10: 4.572 | G10: 0 | H10: 4.844 | I10: 1.624 | J10: 2.612 | K10: 2.027 | L10: 2.173 | M10: 3.628 | N10: -60.046 | O10: -53.7434 | P10: =DEGREES(ATAN2(J10-D10,K10-E10)) -> 60.293678 | Q10: =DEGREES(ATAN2(L10-D10,M10-E10)) -> 79.433394 | R10: =DEGREES(ATAN2(H10-F10,I10-G10)) -> 80.491914 | S10: =S9+MOD(P10-P9+180,360)-180 -> 60.293678 | T10: =T9+MOD(Q10-Q9+180,360)-180 -> 79.433394 | U10: =U9+MOD(R10-R9+180,360)-180 -> 80.491914 | V10: =C10-B10*1000 -> 0
A11: 5 | B11: 0.041666667 | C11: =TimeStep!B11 -> 41.666667 | D11: 1.514 | E11: 0.132 | F11: 4.572 | G11: 0 | H11: 4.856 | I11: 1.622 | J11: 2.627 | K11: 2.044 | L11: 2.201 | M11: 3.649 | N11: -59.9887 | O11: -52.1392 | P11: =DEGREES(ATAN2(J11-D11,K11-E11)) -> 59.79576 | Q11: =DEGREES(ATAN2(L11-D11,M11-E11)) -> 78.947194 | R11: =DEGREES(ATAN2(H11-F11,I11-G11)) -> 80.068613 | S11: =S10+MOD(P11-P10+180,360)-180 -> 59.79576 | T11: =T10+MOD(Q11-Q10+180,360)-180 -> 78.947194 | U11: =U10+MOD(R11-R10+180,360)-180 -> 80.068613 | V11: =C11-B11*1000 -> 7.1054274e-14
A12: 6 | B12: 0.05 | C12: =TimeStep!B12 -> 50 | D12: 1.512 | E12: 0.159 | F12: 4.572 | G12: 0 | H12: 4.868 | I12: 1.62 | J12: 2.641 | K12: 2.06 | L12: 2.229 | M12: 3.669 | N12: -59.8741 | O12: -50.4776 | P12: =DEGREES(ATAN2(J12-D12,K12-E12)) -> 59.294011 | Q12: =DEGREES(ATAN2(L12-D12,M12-E12)) -> 78.454826 | R12: =DEGREES(ATAN2(H12-F12,I12-G12)) -> 79.645364 | S12: =S11+MOD(P12-P11+180,360)-180 -> 59.294011 | T12: =T11+MOD(Q12-Q11+180,360)-180 -> 78.454826 | U12: =U11+MOD(R12-R11+180,360)-180 -> 79.645364 | V12: =C12-B12*1000 -> 0
A13: 7 | B13: 0.058333333 | C13: =TimeStep!B13 -> 58.333333 | D13: 1.509 | E13: 0.185 | F13: 4.572 | G13: 0 | H13: 4.88 | I13: 1.617 | J13: 2.654 | K13: 2.077 | L13: 2.257 | M13: 3.689 | N13: -59.7022 | O13: -48.7587 | P13: =DEGREES(ATAN2(J13-D13,K13-E13)) -> 58.818525 | Q13: =DEGREES(ATAN2(L13-D13,M13-E13)) -> 77.949918 | R13: =DEGREES(ATAN2(H13-F13,I13-G13)) -> 79.215702 | S13: =S12+MOD(P13-P12+180,360)-180 -> 58.818525 | T13: =T12+MOD(Q13-Q12+180,360)-180 -> 77.949918 | U13: =U12+MOD(R13-R12+180,360)-180 -> 79.215702 | V13: =C13-B13*1000 -> 0
A14: 8 | B14: 0.066666667 | C14: =TimeStep!B14 -> 66.666667 | D14: 1.505 | E14: 0.212 | F14: 4.572 | G14: 0 | H14: 4.891 | I14: 1.615 | J14: 2.667 | K14: 2.093 | L14: 2.284 | M14: 3.709 | N14: -59.5303 | O14: -47.0398 | P14: =DEGREES(ATAN2(J14-D14,K14-E14)) -> 58.294031 | Q14: =DEGREES(ATAN2(L14-D14,M14-E14)) -> 77.441704 | R14: =DEGREES(ATAN2(H14-F14,I14-G14)) -> 78.826583 | S14: =S13+MOD(P14-P13+180,360)-180 -> 58.294031 | T14: =T13+MOD(Q14-Q13+180,360)-180 -> 77.441704 | U14: =U13+MOD(R14-R13+180,360)-180 -> 78.826583 | V14: =C14-B14*1000 -> 0
A15: 9 | B15: 0.075 | C15: =TimeStep!B15 -> 75 | D15: 1.501 | E15: 0.238 | F15: 4.572 | G15: 0 | H15: 4.902 | I15: 1.613 | J15: 2.679 | K15: 2.109 | L15: 2.31 | M15: 3.728 | N15: -59.2438 | O15: -45.2637 | P15: =DEGREES(ATAN2(J15-D15,K15-E15)) -> 57.805078 | Q15: =DEGREES(ATAN2(L15-D15,M15-E15)) -> 76.949043 | R15: =DEGREES(ATAN2(H15-F15,I15-G15)) -> 78.437545 | S15: =S14+MOD(P15-P14+180,360)-180 -> 57.805078 | T15: =T14+MOD(Q15-Q14+180,360)-180 -> 76.949043 | U15: =U14+MOD(R15-R14+180,360)-180 -> 78.437545 | V15: =C15-B15*1000 -> 0
A16: 10 | B16: 0.083333333 | C16: =TimeStep!B16 -> 83.333333 | D16: 1.497 | E16: 0.264 | F16: 4.572 | G16: 0 | H16: 4.913 | I16: 1.611 | J16: 2.691 | K16: 2.125 | L16: 2.335 | M16: 3.747 | N16: -58.9574 | O16: -43.4875 | P16: =DEGREES(ATAN2(J16-D16,K16-E16)) -> 57.316153 | Q16: =DEGREES(ATAN2(L16-D16,M16-E16)) -> 76.471918 | R16: =DEGREES(ATAN2(H16-F16,I16-G16)) -> 78.048622 | S16: =S15+MOD(P16-P15+180,360)-180 -> 57.316153 | T16: =T15+MOD(Q16-Q15+180,360)-180 -> 76.471918 | U16: =U15+MOD(R16-R15+180,360)-180 -> 78.048622 | V16: =C16-B16*1000 -> 0
A17: 11 | B17: 0.091666667 | C17: =TimeStep!B17 -> 91.666667 | D17: 1.492 | E17: 0.29 | F17: 4.572 | G17: 0 | H17: 4.923 | I17: 1.609 | J17: 2.702 | K17: 2.141 | L17: 2.361 | M17: 3.766 | N17: -58.6709 | O17: -41.654 | P17: =DEGREES(ATAN2(J17-D17,K17-E17)) -> 56.827327 | Q17: =DEGREES(ATAN2(L17-D17,M17-E17)) -> 75.963757 | R17: =DEGREES(ATAN2(H17-F17,I17-G17)) -> 77.693838 | S17: =S16+MOD(P17-P16+180,360)-180 -> 56.827327 | T17: =T16+MOD(Q17-Q16+180,360)-180 -> 75.963757 | U17: =U16+MOD(R17-R16+180,360)-180 -> 77.693838 | V17: =C17-B17*1000 -> 0
A18: 12 | B18: 0.1 | C18: =TimeStep!B18 -> 100 | D18: 1.487 | E18: 0.316 | F18: 4.572 | G18: 0 | H18: 4.932 | I18: 1.607 | J18: 2.713 | K18: 2.157 | L18: 2.385 | M18: 3.785 | N18: -58.2698 | O18: -39.8206 | P18: =DEGREES(ATAN2(J18-D18,K18-E18)) -> 56.33867 | Q18: =DEGREES(ATAN2(L18-D18,M18-E18)) -> 75.486755 | R18: =DEGREES(ATAN2(H18-F18,I18-G18)) -> 77.373077 | S18: =S17+MOD(P18-P17+180,360)-180 -> 56.33867 | T18: =T17+MOD(Q18-Q17+180,360)-180 -> 75.486755 | U18: =U17+MOD(R18-R17+180,360)-180 -> 77.373077 | V18: =C18-B18*1000 -> 0
... A366: 360 | B366: 3 | C366: =TimeStep!B366 -> 3000 | D366: 1.52 | E366: 0 | F366: 4.572 | G366: 0 | H366: 4.79 | I366: 1.632 | J366: 2.548 | K366: 1.958 | L366: 2.053 | M366: 3.543 | N366: -59.7595 | O366: -59.7595 | P366: =DEGREES(ATAN2(J366-D366,K366-E366)) -> 62.29938 | Q366: =DEGREES(ATAN2(L366-D366,M366-E366)) -> 81.444722 | R366: =DEGREES(ATAN2(H366-F366,I366-G366)) -> 82.391559 | S366: =S365+MOD(P366-P365+180,360)-180 -> 62.29938 | T366: =T365+MOD(Q366-Q365+180,360)-180 -> 81.444722 | U366: =U365+MOD(R366-R365+180,360)-180 -> 82.391559 | V366: =C366-B366*1000 -> 8.1854523e-12

Sheet TimeStep
A1: Time-step calculation
A5: Native step | B5: Calculated time (ms) | C5: Exported time (ms) | D5: Difference (ms) | F5: 360-grid step | G5: 360-grid time (ms)
A6: 0 | B6: =A6*Summary!$B$14 -> 0 | C6: ='Native PMKS'!B6*1000 -> 0 | D6: =B6-C6 -> 0 | F6: 0 | G6: =F6*Summary!$B$17 -> 0
A7: 1 | B7: =A7*Summary!$B$14 -> 8.3333333 | C7: ='Native PMKS'!B7*1000 -> 8.3333333 | D7: =B7-C7 -> 3.375078e-14 | F7: 1 | G7: =F7*Summary!$B$17 -> 8.356546
A8: 2 | B8: =A8*Summary!$B$14 -> 16.666667 | C8: ='Native PMKS'!B8*1000 -> 16.666667 | D8: =B8-C8 -> 6.750156e-14 | F8: 2 | G8: =F8*Summary!$B$17 -> 16.713092
A9: 3 | B9: =A9*Summary!$B$14 -> 25 | C9: ='Native PMKS'!B9*1000 -> 25 | D9: =B9-C9 -> 0 | F9: 3 | G9: =F9*Summary!$B$17 -> 25.069638
A10: 4 | B10: =A10*Summary!$B$14 -> 33.333333 | C10: ='Native PMKS'!B10*1000 -> 33.333333 | D10: =B10-C10 -> 0 | F10: 4 | G10: =F10*Summary!$B$17 -> 33.426184
A11: 5 | B11: =A11*Summary!$B$14 -> 41.666667 | C11: ='Native PMKS'!B11*1000 -> 41.666667 | D11: =B11-C11 -> 7.1054274e-14 | F11: 5 | G11: =F11*Summary!$B$17 -> 41.78273
A12: 6 | B12: =A12*Summary!$B$14 -> 50 | C12: ='Native PMKS'!B12*1000 -> 50 | D12: =B12-C12 -> 0 | F12: 6 | G12: =F12*Summary!$B$17 -> 50.139276
A13: 7 | B13: =A13*Summary!$B$14 -> 58.333333 | C13: ='Native PMKS'!B13*1000 -> 58.333333 | D13: =B13-C13 -> 0 | F13: 7 | G13: =F13*Summary!$B$17 -> 58.495822
A14: 8 | B14: =A14*Summary!$B$14 -> 66.666667 | C14: ='Native PMKS'!B14*1000 -> 66.666667 | D14: =B14-C14 -> 0 | F14: 8 | G14: =F14*Summary!$B$17 -> 66.852368
A15: 9 | B15: =A15*Summary!$B$14 -> 75 | C15: ='Native PMKS'!B15*1000 -> 75 | D15: =B15-C15 -> 0 | F15: 9 | G15: =F15*Summary!$B$17 -> 75.208914
A16: 10 | B16: =A16*Summary!$B$14 -> 83.333333 | C16: ='Native PMKS'!B16*1000 -> 83.333333 | D16: =B16-C16 -> 0 | F16: 10 | G16: =F16*Summary!$B$17 -> 83.56546
A17: 11 | B17: =A17*Summary!$B$14 -> 91.666667 | C17: ='Native PMKS'!B17*1000 -> 91.666667 | D17: =B17-C17 -> 0 | F17: 11 | G17: =F17*Summary!$B$17 -> 91.922006
... A365: 359 | B365: =A365*Summary!$B$14 -> 2991.6667 | C365: ='Native PMKS'!B365*1000 -> 2991.6667 | D365: =B365-C365 -> 8.1854523e-12 | F365: 359 | G365: =F365*Summary!$B$17 -> 3000
A366: 360 | B366: =A366*Summary!$B$14 -> 3000 | C366: ='Native PMKS'!B366*1000 -> 3000 | D366: =B366-C366 -> 8.1854523e-12

Sheet Instructor 360
A1: Instructor 360-point grid
A5: Step | B5: Time (ms) | C5: Native lower row | D5: Native upper row | E5: Weight | F5: Coupler rate (deg/s) | G5: Follower rate (deg/s)
A6: 0 | B6: =TimeStep!G6 -> 0 | C6: =MIN(MATCH(B6,'Native PMKS'!$C$6:$C$366,1),360) -> 1 | D6: =C6+1 -> 2 | E6: =(B6-INDEX('Native PMKS'!$C$6:$C$366,C6))/(INDEX('Native PMKS'!$C$6:$C$366,D6)-INDEX('Native PMKS'!$C$6:$C$366,C6)) -> 0 | F6: =INDEX('Native PMKS'!$N$6:$N$366,C6)+(INDEX('Native PMKS'!$N$6:$N$366,D6)-INDEX('Native PMKS'!$N$6:$N$366,C6))*E6 -> -59.7595 | G6: =INDEX('Native PMKS'!$O$6:$O$366,C6)+(INDEX('Native PMKS'!$O$6:$O$366,D6)-INDEX('Native PMKS'!$O$6:$O$366,C6))*E6 -> -59.7595
A7: 1 | B7: =TimeStep!G7 -> 8.356546 | C7: =MIN(MATCH(B7,'Native PMKS'!$C$6:$C$366,1),360) -> 2 | D7: =C7+1 -> 3 | E7: =(B7-INDEX('Native PMKS'!$C$6:$C$366,C7))/(INDEX('Native PMKS'!$C$6:$C$366,D7)-INDEX('Native PMKS'!$C$6:$C$366,C7)) -> 0.0027855153 | F7: =INDEX('Native PMKS'!$N$6:$N$366,C7)+(INDEX('Native PMKS'!$N$6:$N$366,D7)-INDEX('Native PMKS'!$N$6:$N$366,C7))*E7 -> -59.93156 | G7: =INDEX('Native PMKS'!$O$6:$O$366,C7)+(INDEX('Native PMKS'!$O$6:$O$366,D7)-INDEX('Native PMKS'!$O$6:$O$366,C7))*E7 -> -58.32311
A8: 2 | B8: =TimeStep!G8 -> 16.713092 | C8: =MIN(MATCH(B8,'Native PMKS'!$C$6:$C$366,1),360) -> 3 | D8: =C8+1 -> 4 | E8: =(B8-INDEX('Native PMKS'!$C$6:$C$366,C8))/(INDEX('Native PMKS'!$C$6:$C$366,D8)-INDEX('Native PMKS'!$C$6:$C$366,C8)) -> 0.0055710306 | F8: =INDEX('Native PMKS'!$N$6:$N$366,C8)+(INDEX('Native PMKS'!$N$6:$N$366,D8)-INDEX('Native PMKS'!$N$6:$N$366,C8))*E8 -> -59.989019 | G8: =INDEX('Native PMKS'!$O$6:$O$366,C8)+(INDEX('Native PMKS'!$O$6:$O$366,D8)-INDEX('Native PMKS'!$O$6:$O$366,C8))*E8 -> -56.886082
A9: 3 | B9: =TimeStep!G9 -> 25.069638 | C9: =MIN(MATCH(B9,'Native PMKS'!$C$6:$C$366,1),360) -> 4 | D9: =C9+1 -> 5 | E9: =(B9-INDEX('Native PMKS'!$C$6:$C$366,C9))/(INDEX('Native PMKS'!$C$6:$C$366,D9)-INDEX('Native PMKS'!$C$6:$C$366,C9)) -> 0.008356546 | F9: =INDEX('Native PMKS'!$N$6:$N$366,C9)+(INDEX('Native PMKS'!$N$6:$N$366,D9)-INDEX('Native PMKS'!$N$6:$N$366,C9))*E9 -> -60.046 | G9: =INDEX('Native PMKS'!$O$6:$O$366,C9)+(INDEX('Native PMKS'!$O$6:$O$366,D9)-INDEX('Native PMKS'!$O$6:$O$366,C9))*E9 -> -55.334294
A10: 4 | B10: =TimeStep!G10 -> 33.426184 | C10: =MIN(MATCH(B10,'Native PMKS'!$C$6:$C$366,1),360) -> 5 | D10: =C10+1 -> 6 | E10: =(B10-INDEX('Native PMKS'!$C$6:$C$366,C10))/(INDEX('Native PMKS'!$C$6:$C$366,D10)-INDEX('Native PMKS'!$C$6:$C$366,C10)) -> 0.011142061 | F10: =INDEX('Native PMKS'!$N$6:$N$366,C10)+(INDEX('Native PMKS'!$N$6:$N$366,D10)-INDEX('Native PMKS'!$N$6:$N$366,C10))*E10 -> -60.045362 | G10: =INDEX('Native PMKS'!$O$6:$O$366,C10)+(INDEX('Native PMKS'!$O$6:$O$366,D10)-INDEX('Native PMKS'!$O$6:$O$366,C10))*E10 -> -53.725526
A11: 5 | B11: =TimeStep!G11 -> 41.78273 | C11: =MIN(MATCH(B11,'Native PMKS'!$C$6:$C$366,1),360) -> 6 | D11: =C11+1 -> 7 | E11: =(B11-INDEX('Native PMKS'!$C$6:$C$366,C11))/(INDEX('Native PMKS'!$C$6:$C$366,D11)-INDEX('Native PMKS'!$C$6:$C$366,C11)) -> 0.013927577 | F11: =INDEX('Native PMKS'!$N$6:$N$366,C11)+(INDEX('Native PMKS'!$N$6:$N$366,D11)-INDEX('Native PMKS'!$N$6:$N$366,C11))*E11 -> -59.987104 | G11: =INDEX('Native PMKS'!$O$6:$O$366,C11)+(INDEX('Native PMKS'!$O$6:$O$366,D11)-INDEX('Native PMKS'!$O$6:$O$366,C11))*E11 -> -52.116058
A12: 6 | B12: =TimeStep!G12 -> 50.139276 | C12: =MIN(MATCH(B12,'Native PMKS'!$C$6:$C$366,1),360) -> 7 | D12: =C12+1 -> 8 | E12: =(B12-INDEX('Native PMKS'!$C$6:$C$366,C12))/(INDEX('Native PMKS'!$C$6:$C$366,D12)-INDEX('Native PMKS'!$C$6:$C$366,C12)) -> 0.016713092 | F12: =INDEX('Native PMKS'!$N$6:$N$366,C12)+(INDEX('Native PMKS'!$N$6:$N$366,D12)-INDEX('Native PMKS'!$N$6:$N$366,C12))*E12 -> -59.871227 | G12: =INDEX('Native PMKS'!$O$6:$O$366,C12)+(INDEX('Native PMKS'!$O$6:$O$366,D12)-INDEX('Native PMKS'!$O$6:$O$366,C12))*E12 -> -50.448872
A13: 7 | B13: =TimeStep!G13 -> 58.495822 | C13: =MIN(MATCH(B13,'Native PMKS'!$C$6:$C$366,1),360) -> 8 | D13: =C13+1 -> 9 | E13: =(B13-INDEX('Native PMKS'!$C$6:$C$366,C13))/(INDEX('Native PMKS'!$C$6:$C$366,D13)-INDEX('Native PMKS'!$C$6:$C$366,C13)) -> 0.019498607 | F13: =INDEX('Native PMKS'!$N$6:$N$366,C13)+(INDEX('Native PMKS'!$N$6:$N$366,D13)-INDEX('Native PMKS'!$N$6:$N$366,C13))*E13 -> -59.698848 | G13: =INDEX('Native PMKS'!$O$6:$O$366,C13)+(INDEX('Native PMKS'!$O$6:$O$366,D13)-INDEX('Native PMKS'!$O$6:$O$366,C13))*E13 -> -48.725184
A14: 8 | B14: =TimeStep!G14 -> 66.852368 | C14: =MIN(MATCH(B14,'Native PMKS'!$C$6:$C$366,1),360) -> 9 | D14: =C14+1 -> 10 | E14: =(B14-INDEX('Native PMKS'!$C$6:$C$366,C14))/(INDEX('Native PMKS'!$C$6:$C$366,D14)-INDEX('Native PMKS'!$C$6:$C$366,C14)) -> 0.022284123 | F14: =INDEX('Native PMKS'!$N$6:$N$366,C14)+(INDEX('Native PMKS'!$N$6:$N$366,D14)-INDEX('Native PMKS'!$N$6:$N$366,C14))*E14 -> -59.523916 | G14: =INDEX('Native PMKS'!$O$6:$O$366,C14)+(INDEX('Native PMKS'!$O$6:$O$366,D14)-INDEX('Native PMKS'!$O$6:$O$366,C14))*E14 -> -47.000221
A15: 9 | B15: =TimeStep!G15 -> 75.208914 | C15: =MIN(MATCH(B15,'Native PMKS'!$C$6:$C$366,1),360) -> 10 | D15: =C15+1 -> 11 | E15: =(B15-INDEX('Native PMKS'!$C$6:$C$366,C15))/(INDEX('Native PMKS'!$C$6:$C$366,D15)-INDEX('Native PMKS'!$C$6:$C$366,C15)) -> 0.025069638 | F15: =INDEX('Native PMKS'!$N$6:$N$366,C15)+(INDEX('Native PMKS'!$N$6:$N$366,D15)-INDEX('Native PMKS'!$N$6:$N$366,C15))*E15 -> -59.23662 | G15: =INDEX('Native PMKS'!$O$6:$O$366,C15)+(INDEX('Native PMKS'!$O$6:$O$366,D15)-INDEX('Native PMKS'!$O$6:$O$366,C15))*E15 -> -45.219171
A16: 10 | B16: =TimeStep!G16 -> 83.56546 | C16: =MIN(MATCH(B16,'Native PMKS'!$C$6:$C$366,1),360) -> 11 | D16: =C16+1 -> 12 | E16: =(B16-INDEX('Native PMKS'!$C$6:$C$366,C16))/(INDEX('Native PMKS'!$C$6:$C$366,D16)-INDEX('Native PMKS'!$C$6:$C$366,C16)) -> 0.027855153 | F16: =INDEX('Native PMKS'!$N$6:$N$366,C16)+(INDEX('Native PMKS'!$N$6:$N$366,D16)-INDEX('Native PMKS'!$N$6:$N$366,C16))*E16 -> -58.949419 | G16: =INDEX('Native PMKS'!$O$6:$O$366,C16)+(INDEX('Native PMKS'!$O$6:$O$366,D16)-INDEX('Native PMKS'!$O$6:$O$366,C16))*E16 -> -43.436428
A17: 11 | B17: =TimeStep!G17 -> 91.922006 | C17: =MIN(MATCH(B17,'Native PMKS'!$C$6:$C$366,1),360) -> 12 | D17: =C17+1 -> 13 | E17: =(B17-INDEX('Native PMKS'!$C$6:$C$366,C17))/(INDEX('Native PMKS'!$C$6:$C$366,D17)-INDEX('Native PMKS'!$C$6:$C$366,C17)) -> 0.030640669 | F17: =INDEX('Native PMKS'!$N$6:$N$366,C17)+(INDEX('Native PMKS'!$N$6:$N$366,D17)-INDEX('Native PMKS'!$N$6:$N$366,C17))*E17 -> -58.65861 | G17: =INDEX('Native PMKS'!$O$6:$O$366,C17)+(INDEX('Native PMKS'!$O$6:$O$366,D17)-INDEX('Native PMKS'!$O$6:$O$366,C17))*E17 -> -41.597823
... A365: 359 | B365: =TimeStep!G365 -> 3000 | C365: =MIN(MATCH(B365,'Native PMKS'!$C$6:$C$366,1),360) -> 360 | D365: =C365+1 -> 361 | E365: =(B365-INDEX('Native PMKS'!$C$6:$C$366,C365))/(INDEX('Native PMKS'!$C$6:$C$366,D365)-INDEX('Native PMKS'!$C$6:$C$366,C365)) -> 1 | F365: =INDEX('Native PMKS'!$N$6:$N$366,C365)+(INDEX('Native PMKS'!$N$6:$N$366,D365)-INDEX('Native PMKS'!$N$6:$N$366,C365))*E365 -> -59.7595 | G365: =INDEX('Native PMKS'!$O$6:$O$366,C365)+(INDEX('Native PMKS'!$O$6:$O$366,D365)-INDEX('Native PMKS'!$O$6:$O$366,C365))*E365 -> -59.7595

Sheet BNO1 Rate
A1: Coupler BNO055(1)
A5: Source row | B5: Raw time (ms) | C5: Elapsed time (ms) | D5: PMKS query (ms) | E5: X1 (ms) | F5: X2 (ms) | G5: Y1 | H5: Y2 | I5: Interpolated native | J5: Raw sensor | K5: Measured rate (rad/s) | L5: PMKS native | M5: Residual | N5: Squared error | O5: 360 X1 (ms) | P5: 360 X2 (ms) | Q5: 360 Y1 | R5: 360 Y2 | S5: Interpolated 360 | T5: PMKS rate (rad/s) | U5: Error (rad/s) | W5: Squared error ((rad/s)^2) | AA5: Elapsed time (ms) | AB5: Measured | AC5: PMKS+ 20 rpm
A6: =Summary!B21 -> 694 | B6: =INDEX('Raw Data'!$B$6:$B$1371,MATCH(A6,'Raw Data'!$A$6:$A$1371,0)) -> 14875 | C6: =B6-$B$6 -> 0 | D6: =MOD(C6+Summary!$B$20,Summary!$B$11) -> 2994.7416 | E6: =_xlfn.XLOOKUP(D6,'Native PMKS'!$C$6:$C$366,'Native PMKS'!$C$6:$C$366,,-1) -> 2991.6667 | F6: =_xlfn.XLOOKUP(D6,'Native PMKS'!$C$6:$C$366,'Native PMKS'!$C$6:$C$366,,1) -> 3000 | G6: =_xlfn.XLOOKUP(D6,'Native PMKS'!$C$6:$C$366,'Native PMKS'!$N$6:$N$366,,-1) -> -59.5876 | H6: =_xlfn.XLOOKUP(D6,'Native PMKS'!$C$6:$C$366,'Native PMKS'!$N$6:$N$366,,1) -> -59.7595 | I6: =IF(E6=F6,G6,_xlfn.FORECAST.LINEAR(D6,G6:H6,E6:F6)) -> -59.65103 | J6: =INDEX('Raw Data'!$F$6:$F$1371,MATCH(A6,'Raw Data'!$A$6:$A$1371,0)) -> -63.125 | K6: =J6*1*PI()/180 -> -1.1017391 | L6: =I6*PI()/180 -> -1.0411069 | M6: =K6-L6 -> -0.060632211 | N6: =M6^2 -> 0.003676265 | O6: =_xlfn.XLOOKUP(D6,'Instructor 360'!$B$6:$B$365,'Instructor 360'!$B$6:$B$365,,-1) -> 2991.6435 | P6: =_xlfn.XLOOKUP(D6,'Instructor 360'!$B$6:$B$365,'Instructor 360'!$B$6:$B$365,,1) -> 3000 | Q6: =_xlfn.XLOOKUP(D6,'Instructor 360'!$B$6:$B$365,'Instructor 360'!$F$6:$F$365,,-1) -> -59.586802 | R6: =_xlfn.XLOOKUP(D6,'Instructor 360'!$B$6:$B$365,'Instructor 360'!$F$6:$F$365,,1) -> -59.7595 | S6: =IF(O6=P6,Q6,_xlfn.FORECAST.LINEAR(D6,Q6:R6,O6:P6)) -> -59.650829 | T6: =S6*PI()/180 -> -1.0411034 | U6: =K6-T6 -> -0.060635717 | W6: =U6^2 -> 0.0036766901 | AA6: =C6 -> 0 | AB6: =K6 -> -1.1017391 | AC6: =T6 -> -1.0411034
A7: =A6+1 -> 695 | B7: =INDEX('Raw Data'!$B$6:$B$1371,MATCH(A7,'Raw Data'!$A$6:$A$1371,0)) -> 14896 | C7: =B7-$B$6 -> 21 | D7: =MOD(C7+Summary!$B$20,Summary!$B$11) -> 15.741624 | E7: =_xlfn.XLOOKUP(D7,'Native PMKS'!$C$6:$C$366,'Native PMKS'!$C$6:$C$366,,-1) -> 8.3333333 | F7: =_xlfn.XLOOKUP(D7,'Native PMKS'!$C$6:$C$366,'Native PMKS'!$C$6:$C$366,,1) -> 16.666667 | G7: =_xlfn.XLOOKUP(D7,'Native PMKS'!$C$6:$C$366,'Native PMKS'!$N$6:$N$366,,-1) -> -59.9314 | H7: =_xlfn.XLOOKUP(D7,'Native PMKS'!$C$6:$C$366,'Native PMKS'!$N$6:$N$366,,1) -> -59.9887 | I7: =IF(E7=F7,G7,_xlfn.FORECAST.LINEAR(D7,G7:H7,E7:F7)) -> -59.982339 | J7: =INDEX('Raw Data'!$F$6:$F$1371,MATCH(A7,'Raw Data'!$A$6:$A$1371,0)) -> -63.5625 | K7: =J7*1*PI()/180 -> -1.1093749 | L7: =I7*PI()/180 -> -1.0468893 | M7: =K7-L7 -> -0.06248559 | N7: =M7^2 -> 0.003904449 | O7: =_xlfn.XLOOKUP(D7,'Instructor 360'!$B$6:$B$365,'Instructor 360'!$B$6:$B$365,,-1) -> 8.356546 | P7: =_xlfn.XLOOKUP(D7,'Instructor 360'!$B$6:$B$365,'Instructor 360'!$B$6:$B$365,,1) -> 16.713092 | Q7: =_xlfn.XLOOKUP(D7,'Instructor 360'!$B$6:$B$365,'Instructor 360'!$F$6:$F$365,,-1) -> -59.93156 | R7: =_xlfn.XLOOKUP(D7,'Instructor 360'!$B$6:$B$365,'Instructor 360'!$F$6:$F$365,,1) -> -59.989019 | S7: =IF(O7=P7,Q7,_xlfn.FORECAST.LINEAR(D7,Q7:R7,O7:P7)) -> -59.982339 | T7: =S7*PI()/180 -> -1.0468893 | U7: =K7-T7 -> -0.06248559 | W7: =U7^2 -> 0.003904449 | AA7: =C7 -> 21 | AB7: =K7 -> -1.1093749 | AC7: =T7 -> -1.0468893
A8: =A7+1 -> 696 | B8: =INDEX('Raw Data'!$B$6:$B$1371,MATCH(A8,'Raw Data'!$A$6:$A$1371,0)) -> 14916 | C8: =B8-$B$6 -> 41 | D8: =MOD(C8+Summary!$B$20,Summary!$B$11) -> 35.741624 | E8: =_xlfn.XLOOKUP(D8,'Native PMKS'!$C$6:$C$366,'Native PMKS'!$C$6:$C$366,,-1) -> 33.333333 | F8: =_xlfn.XLOOKUP(D8,'Native PMKS'!$C$6:$C$366,'Native PMKS'!$C$6:$C$366,,1) -> 41.666667 | G8: =_xlfn.XLOOKUP(D8,'Native PMKS'!$C$6:$C$366,'Native PMKS'!$N$6:$N$366,,-1) -> -60.046 | H8: =_xlfn.XLOOKUP(D8,'Native PMKS'!$C$6:$C$366,'Native PMKS'!$N$6:$N$366,,1) -> -59.9887 | I8: =IF(E8=F8,G8,_xlfn.FORECAST.LINEAR(D8,G8:H8,E8:F8)) -> -60.029441 | J8: =INDEX('Raw Data'!$F$6:$F$1371,MATCH(A8,'Raw Data'!$A$6:$A$1371,0)) -> -66.125 | K8: =J8*1*PI()/180 -> -1.154099 | L8: =I8*PI()/180 -> -1.0477114 | M8: =K8-L8 -> -0.10638758 | N8: =M8^2 -> 0.011318317 | O8: =_xlfn.XLOOKUP(D8,'Instructor 360'!$B$6:$B$365,'Instructor 360'!$B$6:$B$365,,-1) -> 33.426184 | P8: =_xlfn.XLOOKUP(D8,'Instructor 360'!$B$6:$B$365,'Instructor 360'!$B$6:$B$365,,1) -> 41.78273 | Q8: =_xlfn.XLOOKUP(D8,'Instructor 360'!$B$6:$B$365,'Instructor 360'!$F$6:$F$365,,-1) -> -60.045362 | R8: =_xlfn.XLOOKUP(D8,'Instructor 360'!$B$6:$B$365,'Instructor 360'!$F$6:$F$365,,1) -> -59.987104 | S8: =IF(O8=P8,Q8,_xlfn.FORECAST.LINEAR(D8,Q8:R8,O8:P8)) -> -60.029219 | T8: =S8*PI()/180 -> -1.0477075 | U8: =K8-T8 -> -0.10639144 | W8: =U8^2 -> 0.011319139 | AA8: =C8 -> 41 | AB8: =K8 -> -1.154099 | AC8: =T8 -> -1.0477075
A9: =A8+1 -> 697 | B9: =INDEX('Raw Data'!$B$6:$B$1371,MATCH(A9,'Raw Data'!$A$6:$A$1371,0)) -> 14937 | C9: =B9-$B$6 -> 62 | D9: =MOD(C9+Summary!$B$20,Summary!$B$11) -> 56.741624 | E9: =_xlfn.XLOOKUP(D9,'Native PMKS'!$C$6:$C$366,'Native PMKS'!$C$6:$C$366,,-1) -> 50 | F9: =_xlfn.XLOOKUP(D9,'Native PMKS'!$C$6:$C$366,'Native PMKS'!$C$6:$C$366,,1) -> 58.333333 | G9: =_xlfn.XLOOKUP(D9,'Native PMKS'!$C$6:$C$366,'Native PMKS'!$N$6:$N$366,,-1) -> -59.8741 | H9: =_xlfn.XLOOKUP(D9,'Native PMKS'!$C$6:$C$366,'Native PMKS'!$N$6:$N$366,,1) -> -59.7022 | I9: =IF(E9=F9,G9,_xlfn.FORECAST.LINEAR(D9,G9:H9,E9:F9)) -> -59.735034 | J9: =INDEX('Raw Data'!$F$6:$F$1371,MATCH(A9,'Raw Data'!$A$6:$A$1371,0)) -> -66.75 | K9: =J9*1*PI()/180 -> -1.1650073 | L9: =I9*PI()/180 -> -1.042573 | M9: =K9-L9 -> -0.12243426 | N9: =M9^2 -> 0.014990147 | O9: =_xlfn.XLOOKUP(D9,'Instructor 360'!$B$6:$B$365,'Instructor 360'!$B$6:$B$365,,-1) -> 50.139276 | P9: =_xlfn.XLOOKUP(D9,'Instructor 360'!$B$6:$B$365,'Instructor 360'!$B$6:$B$365,,1) -> 58.495822 | Q9: =_xlfn.XLOOKUP(D9,'Instructor 360'!$B$6:$B$365,'Instructor 360'!$F$6:$F$365,,-1) -> -59.871227 | R9: =_xlfn.XLOOKUP(D9,'Instructor 360'!$B$6:$B$365,'Instructor 360'!$F$6:$F$365,,1) -> -59.698848 | S9: =IF(O9=P9,Q9,_xlfn.FORECAST.LINEAR(D9,Q9:R9,O9:P9)) -> -59.735034 | T9: =S9*PI()/180 -> -1.042573 | U9: =K9-T9 -> -0.12243426 | W9: =U9^2 -> 0.014990147 | AA9: =C9 -> 62 | AB9: =K9 -> -1.1650073 | AC9: =T9 -> -1.042573
A10: =A9+1 -> 698 | B10: =INDEX('Raw Data'!$B$6:$B$1371,MATCH(A10,'Raw Data'!$A$6:$A$1371,0)) -> 14979 | C10: =B10-$B$6 -> 104 | D10: =MOD(C10+Summary!$B$20,Summary!$B$11) -> 98.741624 | E10: =_xlfn.XLOOKUP(D10,'Native PMKS'!$C$6:$C$366,'Native PMKS'!$C$6:$C$366,,-1) -> 91.666667 | F10: =_xlfn.XLOOKUP(D10,'Native PMKS'!$C$6:$C$366,'Native PMKS'!$C$6:$C$366,,1) -> 100 | G10: =_xlfn.XLOOKUP(D10,'Native PMKS'!$C$6:$C$366,'Native PMKS'!$N$6:$N$366,,-1) -> -58.6709 | H10: =_xlfn.XLOOKUP(D10,'Native PMKS'!$C$6:$C$366,'Native PMKS'!$N$6:$N$366,,1) -> -58.2698 | I10: =IF(E10=F10,G10,_xlfn.FORECAST.LINEAR(D10,G10:H10,E10:F10)) -> -58.330368 | J10: =INDEX('Raw Data'!$F$6:$F$1371,MATCH(A10,'Raw Data'!$A$6:$A$1371,0)) -> -67.0625 | K10: =J10*1*PI()/180 -> -1.1704614 | L10: =I10*PI()/180 -> -1.018057 | M10: =K10-L10 -> -0.15240445 | N10: =M10^2 -> 0.023227117 | O10: =_xlfn.XLOOKUP(D10,'Instructor 360'!$B$6:$B$365,'Instructor 360'!$B$6:$B$365,,-1) -> 91.922006 | P10: =_xlfn.XLOOKUP(D10,'Instructor 360'!$B$6:$B$365,'Instructor 360'!$B$6:$B$365,,1) -> 100.27855 | Q10: =_xlfn.XLOOKUP(D10,'Instructor 360'!$B$6:$B$365,'Instructor 360'!$F$6:$F$365,,-1) -> -58.65861 | R10: =_xlfn.XLOOKUP(D10,'Instructor 360'!$B$6:$B$365,'Instructor 360'!$F$6:$F$365,,1) -> -58.256393 | S10: =IF(O10=P10,Q10,_xlfn.FORECAST.LINEAR(D10,Q10:R10,O10:P10)) -> -58.330368 | T10: =S10*PI()/180 -> -1.018057 | U10: =K10-T10 -> -0.15240445 | W10: =U10^2 -> 0.023227117 | AA10: =C10 -> 104 | AB10: =K10 -> -1.1704614 | AC10: =T10 -> -1.018057
A11: =A10+1 -> 699 | B11: =INDEX('Raw Data'!$B$6:$B$1371,MATCH(A11,'Raw Data'!$A$6:$A$1371,0)) -> 15000 | C11: =B11-$B$6 -> 125 | D11: =MOD(C11+Summary!$B$20,Summary!$B$11) -> 119.74162 | E11: =_xlfn.XLOOKUP(D11,'Native PMKS'!$C$6:$C$366,'Native PMKS'!$C$6:$C$366,,-1) -> 116.66667 | F11: =_xlfn.XLOOKUP(D11,'Native PMKS'!$C$6:$C$366,'Native PMKS'!$C$6:$C$366,,1) -> 125 | G11: =_xlfn.XLOOKUP(D11,'Native PMKS'!$C$6:$C$366,'Native PMKS'!$N$6:$N$366,,-1) -> -57.4104 | H11: =_xlfn.XLOOKUP(D11,'Native PMKS'!$C$6:$C$366,'Native PMKS'!$N$6:$N$366,,1) -> -56.952 | I11: =IF(E11=F11,G11,_xlfn.FORECAST.LINEAR(D11,G11:H11,E11:F11)) -> -57.241253 | J11: =INDEX('Raw Data'!$F$6:$F$1371,MATCH(A11,'Raw Data'!$A$6:$A$1371,0)) -> -68.0625 | K11: =J11*1*PI()/180 -> -1.1879147 | L11: =I11*PI()/180 -> -0.99904833 | M11: =K11-L11 -> -0.18886639 | N11: =M11^2 -> 0.035670515 | O11: =_xlfn.XLOOKUP(D11,'Instructor 360'!$B$6:$B$365,'Instructor 360'!$B$6:$B$365,,-1) -> 116.99164 | P11: =_xlfn.XLOOKUP(D11,'Instructor 360'!$B$6:$B$365,'Instructor 360'!$B$6:$B$365,,1) -> 125.34819 | Q11: =_xlfn.XLOOKUP(D11,'Instructor 360'!$B$6:$B$365,'Instructor 360'!$F$6:$F$365,,-1) -> -57.392524 | R11: =_xlfn.XLOOKUP(D11,'Instructor 360'!$B$6:$B$365,'Instructor 360'!$F$6:$F$365,,1) -> -56.930453 | S11: =IF(O11=P11,Q11,_xlfn.FORECAST.LINEAR(D11,Q11:R11,O11:P11)) -> -57.240465 | T11: =S11*PI()/180 -> -0.99903458 | U11: =K11-T11 -> -0.18888014 | W11: =U11^2 -> 0.035675709 | AA11: =C11 -> 125 | AB11: =K11 -> -1.1879147 | AC11: =T11 -> -0.99903458
A12: =A11+1 -> 700 | B12: =INDEX('Raw Data'!$B$6:$B$1371,MATCH(A12,'Raw Data'!$A$6:$A$1371,0)) -> 15020 | C12: =B12-$B$6 -> 145 | D12: =MOD(C12+Summary!$B$20,Summary!$B$11) -> 139.74162 | E12: =_xlfn.XLOOKUP(D12,'Native PMKS'!$C$6:$C$366,'Native PMKS'!$C$6:$C$366,,-1) -> 133.33333 | F12: =_xlfn.XLOOKUP(D12,'Native PMKS'!$C$6:$C$366,'Native PMKS'!$C$6:$C$366,,1) -> 141.66667 | G12: =_xlfn.XLOOKUP(D12,'Native PMKS'!$C$6:$C$366,'Native PMKS'!$N$6:$N$366,,-1) -> -56.4363 | H12: =_xlfn.XLOOKUP(D12,'Native PMKS'!$C$6:$C$366,'Native PMKS'!$N$6:$N$366,,1) -> -55.9207 | I12: =IF(E12=F12,G12,_xlfn.FORECAST.LINEAR(D12,G12:H12,E12:F12)) -> -56.039806 | J12: =INDEX('Raw Data'!$F$6:$F$1371,MATCH(A12,'Raw Data'!$A$6:$A$1371,0)) -> -66.125 | K12: =J12*1*PI()/180 -> -1.154099 | L12: =I12*PI()/180 -> -0.97807913 | M12: =K12-L12 -> -0.17601984 | N12: =M12^2 -> 0.030982983 | O12: =_xlfn.XLOOKUP(D12,'Instructor 360'!$B$6:$B$365,'Instructor 360'!$B$6:$B$365,,-1) -> 133.70474 | P12: =_xlfn.XLOOKUP(D12,'Instructor 360'!$B$6:$B$365,'Instructor 360'!$B$6:$B$365,,1) -> 142.06128 | Q12: =_xlfn.XLOOKUP(D12,'Instructor 360'!$B$6:$B$365,'Instructor 360'!$F$6:$F$365,,-1) -> -56.413321 | R12: =_xlfn.XLOOKUP(D12,'Instructor 360'!$B$6:$B$365,'Instructor 360'!$F$6:$F$365,,1) -> -55.893566 | S12: =IF(O12=P12,Q12,_xlfn.FORECAST.LINEAR(D12,Q12:R12,O12:P12)) -> -56.037843 | T12: =S12*PI()/180 -> -0.97804486 | U12: =K12-T12 -> -0.17605411 | W12: =U12^2 -> 0.030995049 | AA12: =C12 -> 145 | AB12: =K12 -> -1.154099 | AC12: =T12 -> -0.97804486
A13: =A12+1 -> 701 | B13: =INDEX('Raw Data'!$B$6:$B$1371,MATCH(A13,'Raw Data'!$A$6:$A$1371,0)) -> 15041 | C13: =B13-$B$6 -> 166 | D13: =MOD(C13+Summary!$B$20,Summary!$B$11) -> 160.74162 | E13: =_xlfn.XLOOKUP(D13,'Native PMKS'!$C$6:$C$366,'Native PMKS'!$C$6:$C$366,,-1) -> 158.33333 | F13: =_xlfn.XLOOKUP(D13,'Native PMKS'!$C$6:$C$366,'Native PMKS'!$C$6:$C$366,,1) -> 166.66667 | G13: =_xlfn.XLOOKUP(D13,'Native PMKS'!$C$6:$C$366,'Native PMKS'!$N$6:$N$366,,-1) -> -54.7748 | H13: =_xlfn.XLOOKUP(D13,'Native PMKS'!$C$6:$C$366,'Native PMKS'!$N$6:$N$366,,1) -> -54.1445 | I13: =IF(E13=F13,G13,_xlfn.FORECAST.LINEAR(D13,G13:H13,E13:F13)) -> -54.592647 | J13: =INDEX('Raw Data'!$F$6:$F$1371,MATCH(A13,'Raw Data'!$A$6:$A$1371,0)) -> -65.3125 | K13: =J13*1*PI()/180 -> -1.1399182 | L13: =I13*PI()/180 -> -0.95282143 | M13: =K13-L13 -> -0.18709674 | N13: =M13^2 -> 0.035005189 | O13: =_xlfn.XLOOKUP(D13,'Instructor 360'!$B$6:$B$365,'Instructor 360'!$B$6:$B$365,,-1) -> 158.77437 | P13: =_xlfn.XLOOKUP(D13,'Instructor 360'!$B$6:$B$365,'Instructor 360'!$B$6:$B$365,,1) -> 167.13092 | Q13: =_xlfn.XLOOKUP(D13,'Instructor 360'!$B$6:$B$365,'Instructor 360'!$F$6:$F$365,,-1) -> -54.741442 | R13: =_xlfn.XLOOKUP(D13,'Instructor 360'!$B$6:$B$365,'Instructor 360'!$F$6:$F$365,,1) -> -54.109391 | S13: =IF(O13=P13,Q13,_xlfn.FORECAST.LINEAR(D13,Q13:R13,O13:P13)) -> -54.592648 | T13: =S13*PI()/180 -> -0.95282145 | U13: =K13-T13 -> -0.18709672 | W13: =U13^2 -> 0.035005181 | AA13: =C13 -> 166 | AB13: =K13 -> -1.1399182 | AC13: =T13 -> -0.95282145
A14: =A13+1 -> 702 | B14: =INDEX('Raw Data'!$B$6:$B$1371,MATCH(A14,'Raw Data'!$A$6:$A$1371,0)) -> 15061 | C14: =B14-$B$6 -> 186 | D14: =MOD(C14+Summary!$B$20,Summary!$B$11) -> 180.74162 | E14: =_xlfn.XLOOKUP(D14,'Native PMKS'!$C$6:$C$366,'Native PMKS'!$C$6:$C$366,,-1) -> 175 | F14: =_xlfn.XLOOKUP(D14,'Native PMKS'!$C$6:$C$366,'Native PMKS'!$C$6:$C$366,,1) -> 183.33333 | G14: =_xlfn.XLOOKUP(D14,'Native PMKS'!$C$6:$C$366,'Native PMKS'!$N$6:$N$366,,-1) -> -53.5143 | H14: =_xlfn.XLOOKUP(D14,'Native PMKS'!$C$6:$C$366,'Native PMKS'!$N$6:$N$366,,1) -> -52.884 | I14: =IF(E14=F14,G14,_xlfn.FORECAST.LINEAR(D14,G14:H14,E14:F14)) -> -53.080027 | J14: =INDEX('Raw Data'!$F$6:$F$1371,MATCH(A14,'Raw Data'!$A$6:$A$1371,0)) -> -62.0625 | K14: =J14*1*PI()/180 -> -1.083195 | L14: =I14*PI()/180 -> -0.92642123 | M14: =K14-L14 -> -0.15677374 | N14: =M14^2 -> 0.024578005 | O14: =_xlfn.XLOOKUP(D14,'Instructor 360'!$B$6:$B$365,'Instructor 360'!$B$6:$B$365,,-1) -> 175.48747 | P14: =_xlfn.XLOOKUP(D14,'Instructor 360'!$B$6:$B$365,'Instructor 360'!$B$6:$B$365,,1) -> 183.84401 | Q14: =_xlfn.XLOOKUP(D14,'Instructor 360'!$B$6:$B$365,'Instructor 360'!$F$6:$F$365,,-1) -> -53.47743 | R14: =_xlfn.XLOOKUP(D14,'Instructor 360'!$B$6:$B$365,'Instructor 360'!$F$6:$F$365,,1) -> -52.841869 | S14: =IF(O14=P14,Q14,_xlfn.FORECAST.LINEAR(D14,Q14:R14,O14:P14)) -> -53.077823 | T14: =S14*PI()/180 -> -0.92638276 | U14: =K14-T14 -> -0.1568122 | W14: =U14^2 -> 0.024590067 | AA14: =C14 -> 186 | AB14: =K14 -> -1.083195 | AC14: =T14 -> -0.92638276
A15: =A14+1 -> 703 | B15: =INDEX('Raw Data'!$B$6:$B$1371,MATCH(A15,'Raw Data'!$A$6:$A$1371,0)) -> 15081 | C15: =B15-$B$6 -> 206 | D15: =MOD(C15+Summary!$B$20,Summary!$B$11) -> 200.74162 | E15: =_xlfn.XLOOKUP(D15,'Native PMKS'!$C$6:$C$366,'Native PMKS'!$C$6:$C$366,,-1) -> 200 | F15: =_xlfn.XLOOKUP(D15,'Native PMKS'!$C$6:$C$366,'Native PMKS'!$C$6:$C$366,,1) -> 208.33333 | G15: =_xlfn.XLOOKUP(D15,'Native PMKS'!$C$6:$C$366,'Native PMKS'!$N$6:$N$366,,-1) -> -51.5089 | H15: =_xlfn.XLOOKUP(D15,'Native PMKS'!$C$6:$C$366,'Native PMKS'!$N$6:$N$366,,1) -> -50.8214 | I15: =IF(E15=F15,G15,_xlfn.FORECAST.LINEAR(D15,G15:H15,E15:F15)) -> -51.447716 | J15: =INDEX('Raw Data'!$F$6:$F$1371,MATCH(A15,'Raw Data'!$A$6:$A$1371,0)) -> -60.75 | K15: =J15*1*PI()/180 -> -1.0602875 | L15: =I15*PI()/180 -> -0.89793204 | M15: =K15-L15 -> -0.16235548 | N15: =M15^2 -> 0.026359303 | O15: =_xlfn.XLOOKUP(D15,'Instructor 360'!$B$6:$B$365,'Instructor 360'!$B$6:$B$365,,-1) -> 200.5571 | P15: =_xlfn.XLOOKUP(D15,'Instructor 360'!$B$6:$B$365,'Instructor 360'!$B$6:$B$365,,1) -> 208.91365 | Q15: =_xlfn.XLOOKUP(D15,'Instructor 360'!$B$6:$B$365,'Instructor 360'!$F$6:$F$365,,-1) -> -51.462939 | R15: =_xlfn.XLOOKUP(D15,'Instructor 360'!$B$6:$B$365,'Instructor 360'!$F$6:$F$365,,1) -> -50.773517 | S15: =IF(O15=P15,Q15,_xlfn.FORECAST.LINEAR(D15,Q15:R15,O15:P15)) -> -51.447716 | T15: =S15*PI()/180 -> -0.89793203 | U15: =K15-T15 -> -0.16235549 | W15: =U15^2 -> 0.026359304 | AA15: =C15 -> 206 | AB15: =K15 -> -1.0602875 | AC15: =T15 -> -0.89793203
A16: =A15+1 -> 704 | B16: =INDEX('Raw Data'!$B$6:$B$1371,MATCH(A16,'Raw Data'!$A$6:$A$1371,0)) -> 15103 | C16: =B16-$B$6 -> 228 | D16: =MOD(C16+Summary!$B$20,Summary!$B$11) -> 222.74162 | E16: =_xlfn.XLOOKUP(D16,'Native PMKS'!$C$6:$C$366,'Native PMKS'!$C$6:$C$366,,-1) -> 216.66667 | F16: =_xlfn.XLOOKUP(D16,'Native PMKS'!$C$6:$C$366,'Native PMKS'!$C$6:$C$366,,1) -> 225 | G16: =_xlfn.XLOOKUP(D16,'Native PMKS'!$C$6:$C$366,'Native PMKS'!$N$6:$N$366,,-1) -> -50.1338 | H16: =_xlfn.XLOOKUP(D16,'Native PMKS'!$C$6:$C$366,'Native PMKS'!$N$6:$N$366,,1) -> -49.389 | I16: =IF(E16=F16,G16,_xlfn.FORECAST.LINEAR(D16,G16:H16,E16:F16)) -> -49.590845 | J16: =INDEX('Raw Data'!$F$6:$F$1371,MATCH(A16,'Raw Data'!$A$6:$A$1371,0)) -> -58.0625 | K16: =J16*1*PI()/180 -> -1.0133818 | L16: =I16*PI()/180 -> -0.86552352 | M16: =K16-L16 -> -0.14785828 | N16: =M16^2 -> 0.021862071 | O16: =_xlfn.XLOOKUP(D16,'Instructor 360'!$B$6:$B$365,'Instructor 360'!$B$6:$B$365,,-1) -> 217.27019 | P16: =_xlfn.XLOOKUP(D16,'Instructor 360'!$B$6:$B$365,'Instructor 360'!$B$6:$B$365,,1) -> 225.62674 | Q16: =_xlfn.XLOOKUP(D16,'Instructor 360'!$B$6:$B$365,'Instructor 360'!$F$6:$F$365,,-1) -> -50.079859 | R16: =_xlfn.XLOOKUP(D16,'Instructor 360'!$B$6:$B$365,'Instructor 360'!$F$6:$F$365,,1) -> -49.332977 | S16: =IF(O16=P16,Q16,_xlfn.FORECAST.LINEAR(D16,Q16:R16,O16:P16)) -> -49.59084 | T16: =S16*PI()/180 -> -0.86552343 | U16: =K16-T16 -> -0.14785837 | W16: =U16^2 -> 0.021862096 | AA16: =C16 -> 228 | AB16: =K16 -> -1.0133818 | AC16: =T16 -> -0.86552343
A17: =A16+1 -> 705 | B17: =INDEX('Raw Data'!$B$6:$B$1371,MATCH(A17,'Raw Data'!$A$6:$A$1371,0)) -> 15124 | C17: =B17-$B$6 -> 249 | D17: =MOD(C17+Summary!$B$20,Summary!$B$11) -> 243.74162 | E17: =_xlfn.XLOOKUP(D17,'Native PMKS'!$C$6:$C$366,'Native PMKS'!$C$6:$C$366,,-1) -> 241.66667 | F17: =_xlfn.XLOOKUP(D17,'Native PMKS'!$C$6:$C$366,'Native PMKS'!$C$6:$C$366,,1) -> 250 | G17: =_xlfn.XLOOKUP(D17,'Native PMKS'!$C$6:$C$366,'Native PMKS'!$N$6:$N$366,,-1) -> -47.8993 | H17: =_xlfn.XLOOKUP(D17,'Native PMKS'!$C$6:$C$366,'Native PMKS'!$N$6:$N$366,,1) -> -47.1544 | I17: =IF(E17=F17,G17,_xlfn.FORECAST.LINEAR(D17,G17:H17,E17:F17)) -> -47.713824 | J17: =INDEX('Raw Data'!$F$6:$F$1371,MATCH(A17,'Raw Data'!$A$6:$A$1371,0)) -> -56.125 | K17: =J17*1*PI()/180 -> -0.97956604 | L17: =I17*PI()/180 -> -0.83276332 | M17: =K17-L17 -> -0.14680272 | N17: =M17^2 -> 0.021551039 | O17: =_xlfn.XLOOKUP(D17,'Instructor 360'!$B$6:$B$365,'Instructor 360'!$B$6:$B$365,,-1) -> 242.33983 | P17: =_xlfn.XLOOKUP(D17,'Instructor 360'!$B$6:$B$365,'Instructor 360'!$B$6:$B$365,,1) -> 250.69638 | Q17: =_xlfn.XLOOKUP(D17,'Instructor 360'!$B$6:$B$365,'Instructor 360'!$F$6:$F$365,,-1) -> -47.839127 | R17: =_xlfn.XLOOKUP(D17,'Instructor 360'!$B$6:$B$365,'Instructor 360'!$F$6:$F$365,,1) -> -47.09216 | S17: =IF(O17=P17,Q17,_xlfn.FORECAST.LINEAR(D17,Q17:R17,O17:P17)) -> -47.713825 | T17: =S17*PI()/180 -> -0.83276335 | U17: =K17-T17 -> -0.1468027 | W17: =U17^2 -> 0.021551031 | AA17: =C17 -> 249 | AB17: =K17 -> -0.97956604 | AC17: =T17 -> -0.83276335
A18: =A17+1 -> 706 | B18: =INDEX('Raw Data'!$B$6:$B$1371,MATCH(A18,'Raw Data'!$A$6:$A$1371,0)) -> 15147 | C18: =B18-$B$6 -> 272 | D18: =MOD(C18+Summary!$B$20,Summary!$B$11) -> 266.74162 | E18: =_xlfn.XLOOKUP(D18,'Native PMKS'!$C$6:$C$366,'Native PMKS'!$C$6:$C$366,,-1) -> 266.66667 | F18: =_xlfn.XLOOKUP(D18,'Native PMKS'!$C$6:$C$366,'Native PMKS'!$C$6:$C$366,,1) -> 275 | G18: =_xlfn.XLOOKUP(D18,'Native PMKS'!$C$6:$C$366,'Native PMKS'!$N$6:$N$366,,-1) -> -45.6647 | H18: =_xlfn.XLOOKUP(D18,'Native PMKS'!$C$6:$C$366,'Native PMKS'!$N$6:$N$366,,1) -> -44.9199 | I18: =IF(E18=F18,G18,_xlfn.FORECAST.LINEAR(D18,G18:H18,E18:F18)) -> -45.658001 | J18: =INDEX('Raw Data'!$F$6:$F$1371,MATCH(A18,'Raw Data'!$A$6:$A$1371,0)) -> -53.9375 | K18: =J18*1*PI()/180 -> -0.94138697 | L18: =I18*PI()/180 -> -0.79688244 | M18: =K18-L18 -> -0.14450452 | N18: =M18^2 -> 0.020881558 | O18: =_xlfn.XLOOKUP(D18,'Instructor 360'!$B$6:$B$365,'Instructor 360'!$B$6:$B$365,,-1) -> 259.05292 | P18: =_xlfn.XLOOKUP(D18,'Instructor 360'!$B$6:$B$365,'Instructor 360'!$B$6:$B$365,,1) -> 267.40947 | Q18: =_xlfn.XLOOKUP(D18,'Instructor 360'!$B$6:$B$365,'Instructor 360'!$F$6:$F$365,,-1) -> -46.345277 | R18: =_xlfn.XLOOKUP(D18,'Instructor 360'!$B$6:$B$365,'Instructor 360'!$F$6:$F$365,,1) -> -45.598311 | S18: =IF(O18=P18,Q18,_xlfn.FORECAST.LINEAR(D18,Q18:R18,O18:P18)) -> -45.658008 | T18: =S18*PI()/180 -> -0.79688257 | U18: =K18-T18 -> -0.1445044 | W18: =U18^2 -> 0.020881521 | AA18: =C18 -> 272 | AB18: =K18 -> -0.94138697 | AC18: =T18 -> -0.79688257
... A140: =A139+1 -> 828 | B140: =INDEX('Raw Data'!$B$6:$B$1371,MATCH(A140,'Raw Data'!$A$6:$A$1371,0)) -> 17778 | C140: =B140-$B$6 -> 2903 | D140: =MOD(C140+Summary!$B$20,Summary!$B$11) -> 2897.7416 | E140: =_xlfn.XLOOKUP(D140,'Native PMKS'!$C$6:$C$366,'Native PMKS'!$C$6:$C$366,,-1) -> 2891.6667 | F140: =_xlfn.XLOOKUP(D140,'Native PMKS'!$C$6:$C$366,'Native PMKS'!$C$6:$C$366,,1) -> 2900 | G140: =_xlfn.XLOOKUP(D140,'Native PMKS'!$C$6:$C$366,'Native PMKS'!$N$6:$N$366,,-1) -> -52.8267 | H140: =_xlfn.XLOOKUP(D140,'Native PMKS'!$C$6:$C$366,'Native PMKS'!$N$6:$N$366,,1) -> -53.6861 | I140: =IF(E140=F140,G140,_xlfn.FORECAST.LINEAR(D140,G140:H140,E140:F140)) -> -53.453198 | J140: =INDEX('Raw Data'!$F$6:$F$1371,MATCH(A140,'Raw Data'!$A$6:$A$1371,0)) -> -58.9375 | K140: =J140*1*PI()/180 -> -1.0286534 | L140: =I140*PI()/180 -> -0.9329343 | M140: =K140-L140 -> -0.095719124 | N140: =M140^2 -> 0.0091621507 | O140: =_xlfn.XLOOKUP(D140,'Instructor 360'!$B$6:$B$365,'Instructor 360'!$B$6:$B$365,,-1) -> 2891.3649 | P140: =_xlfn.XLOOKUP(D140,'Instructor 360'!$B$6:$B$365,'Instructor 360'!$B$6:$B$365,,1) -> 2899.7214 | Q140: =_xlfn.XLOOKUP(D140,'Instructor 360'!$B$6:$B$365,'Instructor 360'!$F$6:$F$365,,-1) -> -52.793505 | R140: =_xlfn.XLOOKUP(D140,'Instructor 360'!$B$6:$B$365,'Instructor 360'!$F$6:$F$365,,1) -> -53.657374 | S140: =IF(O140=P140,Q140,_xlfn.FORECAST.LINEAR(D140,Q140:R140,O140:P140)) -> -53.452707 | T140: =S140*PI()/180 -> -0.93292572 | U140: =K140-T140 -> -0.095727704 | W140: =U140^2 -> 0.0091637933 | AA140: =C140 -> 2903 | AB140: =K140 -> -1.0286534 | AC140: =T140 -> -0.93292572

Sheet MPU Rate
A1: Coupler MPU6050
A5: Source row | B5: Raw time (ms) | C5: Elapsed time (ms) | D5: PMKS query (ms) | E5: X1 (ms) | F5: X2 (ms) | G5: Y1 | H5: Y2 | I5: Interpolated native | J5: Raw sensor | K5: Measured rate (rad/s) | L5: PMKS native | M5: Residual | N5: Squared error | O5: 360 X1 (ms) | P5: 360 X2 (ms) | Q5: 360 Y1 | R5: 360 Y2 | S5: Interpolated 360 | T5: PMKS rate (rad/s) | U5: Error (rad/s) | W5: Squared error ((rad/s)^2) | AA5: Elapsed time (ms) | AB5: Measured | AC5: PMKS+ 20 rpm
A6: =Summary!B21 -> 694 | B6: =INDEX('Raw Data'!$B$6:$B$1371,MATCH(A6,'Raw Data'!$A$6:$A$1371,0)) -> 14875 | C6: =B6-$B$6 -> 0 | D6: =MOD(C6+Summary!$B$20,Summary!$B$11) -> 2994.7416 | E6: =_xlfn.XLOOKUP(D6,'Native PMKS'!$C$6:$C$366,'Native PMKS'!$C$6:$C$366,,-1) -> 2991.6667 | F6: =_xlfn.XLOOKUP(D6,'Native PMKS'!$C$6:$C$366,'Native PMKS'!$C$6:$C$366,,1) -> 3000 | G6: =_xlfn.XLOOKUP(D6,'Native PMKS'!$C$6:$C$366,'Native PMKS'!$N$6:$N$366,,-1) -> -59.5876 | H6: =_xlfn.XLOOKUP(D6,'Native PMKS'!$C$6:$C$366,'Native PMKS'!$N$6:$N$366,,1) -> -59.7595 | I6: =IF(E6=F6,G6,_xlfn.FORECAST.LINEAR(D6,G6:H6,E6:F6)) -> -59.65103 | J6: =INDEX('Raw Data'!$S$6:$S$1371,MATCH(A6,'Raw Data'!$A$6:$A$1371,0)) -> 62.228027 | K6: =J6*-1*PI()/180 -> -1.086084 | L6: =I6*PI()/180 -> -1.0411069 | M6: =K6-L6 -> -0.044977085 | N6: =M6^2 -> 0.0020229381 | O6: =_xlfn.XLOOKUP(D6,'Instructor 360'!$B$6:$B$365,'Instructor 360'!$B$6:$B$365,,-1) -> 2991.6435 | P6: =_xlfn.XLOOKUP(D6,'Instructor 360'!$B$6:$B$365,'Instructor 360'!$B$6:$B$365,,1) -> 3000 | Q6: =_xlfn.XLOOKUP(D6,'Instructor 360'!$B$6:$B$365,'Instructor 360'!$F$6:$F$365,,-1) -> -59.586802 | R6: =_xlfn.XLOOKUP(D6,'Instructor 360'!$B$6:$B$365,'Instructor 360'!$F$6:$F$365,,1) -> -59.7595 | S6: =IF(O6=P6,Q6,_xlfn.FORECAST.LINEAR(D6,Q6:R6,O6:P6)) -> -59.650829 | T6: =S6*PI()/180 -> -1.0411034 | U6: =K6-T6 -> -0.044980591 | W6: =U6^2 -> 0.0020232535 | AA6: =C6 -> 0 | AB6: =K6 -> -1.086084 | AC6: =T6 -> -1.0411034
A7: =A6+1 -> 695 | B7: =INDEX('Raw Data'!$B$6:$B$1371,MATCH(A7,'Raw Data'!$A$6:$A$1371,0)) -> 14896 | C7: =B7-$B$6 -> 21 | D7: =MOD(C7+Summary!$B$20,Summary!$B$11) -> 15.741624 | E7: =_xlfn.XLOOKUP(D7,'Native PMKS'!$C$6:$C$366,'Native PMKS'!$C$6:$C$366,,-1) -> 8.3333333 | F7: =_xlfn.XLOOKUP(D7,'Native PMKS'!$C$6:$C$366,'Native PMKS'!$C$6:$C$366,,1) -> 16.666667 | G7: =_xlfn.XLOOKUP(D7,'Native PMKS'!$C$6:$C$366,'Native PMKS'!$N$6:$N$366,,-1) -> -59.9314 | H7: =_xlfn.XLOOKUP(D7,'Native PMKS'!$C$6:$C$366,'Native PMKS'!$N$6:$N$366,,1) -> -59.9887 | I7: =IF(E7=F7,G7,_xlfn.FORECAST.LINEAR(D7,G7:H7,E7:F7)) -> -59.982339 | J7: =INDEX('Raw Data'!$S$6:$S$1371,MATCH(A7,'Raw Data'!$A$6:$A$1371,0)) -> 65.05246 | K7: =J7*-1*PI()/180 -> -1.1353796 | L7: =I7*PI()/180 -> -1.0468893 | M7: =K7-L7 -> -0.088490293 | N7: =M7^2 -> 0.0078305319 | O7: =_xlfn.XLOOKUP(D7,'Instructor 360'!$B$6:$B$365,'Instructor 360'!$B$6:$B$365,,-1) -> 8.356546 | P7: =_xlfn.XLOOKUP(D7,'Instructor 360'!$B$6:$B$365,'Instructor 360'!$B$6:$B$365,,1) -> 16.713092 | Q7: =_xlfn.XLOOKUP(D7,'Instructor 360'!$B$6:$B$365,'Instructor 360'!$F$6:$F$365,,-1) -> -59.93156 | R7: =_xlfn.XLOOKUP(D7,'Instructor 360'!$B$6:$B$365,'Instructor 360'!$F$6:$F$365,,1) -> -59.989019 | S7: =IF(O7=P7,Q7,_xlfn.FORECAST.LINEAR(D7,Q7:R7,O7:P7)) -> -59.982339 | T7: =S7*PI()/180 -> -1.0468893 | U7: =K7-T7 -> -0.088490293 | W7: =U7^2 -> 0.0078305319 | AA7: =C7 -> 21 | AB7: =K7 -> -1.1353796 | AC7: =T7 -> -1.0468893
A8: =A7+1 -> 696 | B8: =INDEX('Raw Data'!$B$6:$B$1371,MATCH(A8,'Raw Data'!$A$6:$A$1371,0)) -> 14916 | C8: =B8-$B$6 -> 41 | D8: =MOD(C8+Summary!$B$20,Summary!$B$11) -> 35.741624 | E8: =_xlfn.XLOOKUP(D8,'Native PMKS'!$C$6:$C$366,'Native PMKS'!$C$6:$C$366,,-1) -> 33.333333 | F8: =_xlfn.XLOOKUP(D8,'Native PMKS'!$C$6:$C$366,'Native PMKS'!$C$6:$C$366,,1) -> 41.666667 | G8: =_xlfn.XLOOKUP(D8,'Native PMKS'!$C$6:$C$366,'Native PMKS'!$N$6:$N$366,,-1) -> -60.046 | H8: =_xlfn.XLOOKUP(D8,'Native PMKS'!$C$6:$C$366,'Native PMKS'!$N$6:$N$366,,1) -> -59.9887 | I8: =IF(E8=F8,G8,_xlfn.FORECAST.LINEAR(D8,G8:H8,E8:F8)) -> -60.029441 | J8: =INDEX('Raw Data'!$S$6:$S$1371,MATCH(A8,'Raw Data'!$A$6:$A$1371,0)) -> 64.823448 | K8: =J8*-1*PI()/180 -> -1.1313826 | L8: =I8*PI()/180 -> -1.0477114 | M8: =K8-L8 -> -0.083671217 | N8: =M8^2 -> 0.0070008725 | O8: =_xlfn.XLOOKUP(D8,'Instructor 360'!$B$6:$B$365,'Instructor 360'!$B$6:$B$365,,-1) -> 33.426184 | P8: =_xlfn.XLOOKUP(D8,'Instructor 360'!$B$6:$B$365,'Instructor 360'!$B$6:$B$365,,1) -> 41.78273 | Q8: =_xlfn.XLOOKUP(D8,'Instructor 360'!$B$6:$B$365,'Instructor 360'!$F$6:$F$365,,-1) -> -60.045362 | R8: =_xlfn.XLOOKUP(D8,'Instructor 360'!$B$6:$B$365,'Instructor 360'!$F$6:$F$365,,1) -> -59.987104 | S8: =IF(O8=P8,Q8,_xlfn.FORECAST.LINEAR(D8,Q8:R8,O8:P8)) -> -60.029219 | T8: =S8*PI()/180 -> -1.0477075 | U8: =K8-T8 -> -0.083675076 | W8: =U8^2 -> 0.0070015184 | AA8: =C8 -> 41 | AB8: =K8 -> -1.1313826 | AC8: =T8 -> -1.0477075
A9: =A8+1 -> 697 | B9: =INDEX('Raw Data'!$B$6:$B$1371,MATCH(A9,'Raw Data'!$A$6:$A$1371,0)) -> 14937 | C9: =B9-$B$6 -> 62 | D9: =MOD(C9+Summary!$B$20,Summary!$B$11) -> 56.741624 | E9: =_xlfn.XLOOKUP(D9,'Native PMKS'!$C$6:$C$366,'Native PMKS'!$C$6:$C$366,,-1) -> 50 | F9: =_xlfn.XLOOKUP(D9,'Native PMKS'!$C$6:$C$366,'Native PMKS'!$C$6:$C$366,,1) -> 58.333333 | G9: =_xlfn.XLOOKUP(D9,'Native PMKS'!$C$6:$C$366,'Native PMKS'!$N$6:$N$366,,-1) -> -59.8741 | H9: =_xlfn.XLOOKUP(D9,'Native PMKS'!$C$6:$C$366,'Native PMKS'!$N$6:$N$366,,1) -> -59.7022 | I9: =IF(E9=F9,G9,_xlfn.FORECAST.LINEAR(D9,G9:H9,E9:F9)) -> -59.735034 | J9: =INDEX('Raw Data'!$S$6:$S$1371,MATCH(A9,'Raw Data'!$A$6:$A$1371,0)) -> 66.457039 | K9: =J9*-1*PI()/180 -> -1.1598941 | L9: =I9*PI()/180 -> -1.042573 | M9: =K9-L9 -> -0.11732112 | N9: =M9^2 -> 0.013764245 | O9: =_xlfn.XLOOKUP(D9,'Instructor 360'!$B$6:$B$365,'Instructor 360'!$B$6:$B$365,,-1) -> 50.139276 | P9: =_xlfn.XLOOKUP(D9,'Instructor 360'!$B$6:$B$365,'Instructor 360'!$B$6:$B$365,,1) -> 58.495822 | Q9: =_xlfn.XLOOKUP(D9,'Instructor 360'!$B$6:$B$365,'Instructor 360'!$F$6:$F$365,,-1) -> -59.871227 | R9: =_xlfn.XLOOKUP(D9,'Instructor 360'!$B$6:$B$365,'Instructor 360'!$F$6:$F$365,,1) -> -59.698848 | S9: =IF(O9=P9,Q9,_xlfn.FORECAST.LINEAR(D9,Q9:R9,O9:P9)) -> -59.735034 | T9: =S9*PI()/180 -> -1.042573 | U9: =K9-T9 -> -0.11732112 | W9: =U9^2 -> 0.013764245 | AA9: =C9 -> 62 | AB9: =K9 -> -1.1598941 | AC9: =T9 -> -1.042573
A10: =A9+1 -> 698 | B10: =INDEX('Raw Data'!$B$6:$B$1371,MATCH(A10,'Raw Data'!$A$6:$A$1371,0)) -> 14979 | C10: =B10-$B$6 -> 104 | D10: =MOD(C10+Summary!$B$20,Summary!$B$11) -> 98.741624 | E10: =_xlfn.XLOOKUP(D10,'Native PMKS'!$C$6:$C$366,'Native PMKS'!$C$6:$C$366,,-1) -> 91.666667 | F10: =_xlfn.XLOOKUP(D10,'Native PMKS'!$C$6:$C$366,'Native PMKS'!$C$6:$C$366,,1) -> 100 | G10: =_xlfn.XLOOKUP(D10,'Native PMKS'!$C$6:$C$366,'Native PMKS'!$N$6:$N$366,,-1) -> -58.6709 | H10: =_xlfn.XLOOKUP(D10,'Native PMKS'!$C$6:$C$366,'Native PMKS'!$N$6:$N$366,,1) -> -58.2698 | I10: =IF(E10=F10,G10,_xlfn.FORECAST.LINEAR(D10,G10:H10,E10:F10)) -> -58.330368 | J10: =INDEX('Raw Data'!$S$6:$S$1371,MATCH(A10,'Raw Data'!$A$6:$A$1371,0)) -> 66.212769 | K10: =J10*-1*PI()/180 -> -1.1556308 | L10: =I10*PI()/180 -> -1.018057 | M10: =K10-L10 -> -0.13757384 | N10: =M10^2 -> 0.018926561 | O10: =_xlfn.XLOOKUP(D10,'Instructor 360'!$B$6:$B$365,'Instructor 360'!$B$6:$B$365,,-1) -> 91.922006 | P10: =_xlfn.XLOOKUP(D10,'Instructor 360'!$B$6:$B$365,'Instructor 360'!$B$6:$B$365,,1) -> 100.27855 | Q10: =_xlfn.XLOOKUP(D10,'Instructor 360'!$B$6:$B$365,'Instructor 360'!$F$6:$F$365,,-1) -> -58.65861 | R10: =_xlfn.XLOOKUP(D10,'Instructor 360'!$B$6:$B$365,'Instructor 360'!$F$6:$F$365,,1) -> -58.256393 | S10: =IF(O10=P10,Q10,_xlfn.FORECAST.LINEAR(D10,Q10:R10,O10:P10)) -> -58.330368 | T10: =S10*PI()/180 -> -1.018057 | U10: =K10-T10 -> -0.13757384 | W10: =U10^2 -> 0.018926561 | AA10: =C10 -> 104 | AB10: =K10 -> -1.1556308 | AC10: =T10 -> -1.018057
A11: =A10+1 -> 699 | B11: =INDEX('Raw Data'!$B$6:$B$1371,MATCH(A11,'Raw Data'!$A$6:$A$1371,0)) -> 15000 | C11: =B11-$B$6 -> 125 | D11: =MOD(C11+Summary!$B$20,Summary!$B$11) -> 119.74162 | E11: =_xlfn.XLOOKUP(D11,'Native PMKS'!$C$6:$C$366,'Native PMKS'!$C$6:$C$366,,-1) -> 116.66667 | F11: =_xlfn.XLOOKUP(D11,'Native PMKS'!$C$6:$C$366,'Native PMKS'!$C$6:$C$366,,1) -> 125 | G11: =_xlfn.XLOOKUP(D11,'Native PMKS'!$C$6:$C$366,'Native PMKS'!$N$6:$N$366,,-1) -> -57.4104 | H11: =_xlfn.XLOOKUP(D11,'Native PMKS'!$C$6:$C$366,'Native PMKS'!$N$6:$N$366,,1) -> -56.952 | I11: =IF(E11=F11,G11,_xlfn.FORECAST.LINEAR(D11,G11:H11,E11:F11)) -> -57.241253 | J11: =INDEX('Raw Data'!$S$6:$S$1371,MATCH(A11,'Raw Data'!$A$6:$A$1371,0)) -> 63.586807 | K11: =J11*-1*PI()/180 -> -1.1097991 | L11: =I11*PI()/180 -> -0.99904833 | M11: =K11-L11 -> -0.11075082 | N11: =M11^2 -> 0.012265744 | O11: =_xlfn.XLOOKUP(D11,'Instructor 360'!$B$6:$B$365,'Instructor 360'!$B$6:$B$365,,-1) -> 116.99164 | P11: =_xlfn.XLOOKUP(D11,'Instructor 360'!$B$6:$B$365,'Instructor 360'!$B$6:$B$365,,1) -> 125.34819 | Q11: =_xlfn.XLOOKUP(D11,'Instructor 360'!$B$6:$B$365,'Instructor 360'!$F$6:$F$365,,-1) -> -57.392524 | R11: =_xlfn.XLOOKUP(D11,'Instructor 360'!$B$6:$B$365,'Instructor 360'!$F$6:$F$365,,1) -> -56.930453 | S11: =IF(O11=P11,Q11,_xlfn.FORECAST.LINEAR(D11,Q11:R11,O11:P11)) -> -57.240465 | T11: =S11*PI()/180 -> -0.99903458 | U11: =K11-T11 -> -0.11076457 | W11: =U11^2 -> 0.01226879 | AA11: =C11 -> 125 | AB11: =K11 -> -1.1097991 | AC11: =T11 -> -0.99903458
